Workbook

Sheet Dashboard
B1: Total | D1: Differential | F1: Flux | H1: Spending | J1: Net Worth | W1: Current Paid | Y1: Total Paid | AA1: Interest | AE1: Gas Data (Averages)
A2: This Month | B2: ='Data Analysis'!K58 -> 3160.6221 | D2: ='Data Analysis'!AJ58 -> 88.939127 | F2: ='Data Analysis'!AG58 -> 17.76 | H2: ='Data Analysis'!R58 -> 3347.6809 | V2: Original | W2: ='Student Loans'!X3 -> 23664.19 | Y2: ='Student Loans'!D16 -> 51631.54 | AA2: ='Student Loans'!E16 -> 8994 | AC2: CPG | AD2: MPG | AE2: MPD | AF2: CPM
A3: Last Month | B3: ='Data Analysis'!K57 -> 3071.6829 | D3: ='Data Analysis'!AJ57 -> 84.860791 | F3: ='Data Analysis'!AG57 -> -123.11 | H3: ='Data Analysis'!R57 -> 2825.5992 | V3: Saved | W3: =Y3-Y2 -> -4055.0151 | Y3: ='Student Loans'!D17 -> 47576.525 | AA3: ='Student Loans'!E17 -> 4938.9849 | AC3: =Gas!N3 -> 4.4404006 | AD3: =Gas!O3 -> 25.461285 | AE3: =Gas!P3 -> 6.0694424 | AF3: =Gas!Q3 -> 0.1752112

Sheet Data
A2: 2020 | C2: èè INFLOW èè | F2: èèèè OUTFLOW èèèè
A3: êêê | B3: 43952 | F3: Necessary | I3: Unnecessary | L3: Savings B | M3: Savings A | N3: Stocks
F5: 240 | G5: Food | I5: 205 | J5: Green | O5: Flux | P5: Net | Q5: Estimated | U5: Actual | W5: Net | X5: Flux | Z5: Cash | AB5: Bank
B6: 43959 | C6: 505.71 | D6: Work | F6: 120 | G6: Gas | I6: 9.99 | J6: Spotify | Q6: =U6 -> 104.64 | R6: Balance | U6: =AB6+Z6 -> 104.64 | Y6: Wallet | Z6: 21 | AA6: Checking | AB6: 83.64
B7: 43973 | C7: 308.46 | D7: Work | F7: 712.86 | G7: UCO | I7: 6.99 | J7: Disney Plus | Q7: =U7 -> 645.96 | R7: Savings | U7: =AB7+Z7+Z8 -> 645.96 | Y7: Drawer | Z7: 144 | AA7: Savings | AB7: 401.96
Q8: =U8 -> 750.6 | R8: Total | U8: =AB6+AB7+Z6+Z7+Z8 -> 750.6 | Y8: Coins | Z8: 100
A9: êêê | B9: 43983
F10: =9+34.9+9.27+8.87+9.27+9+10.57+9.27+7+7+32.55+8+10+9+8+7+41.06+9+9 -> 247.76 | G10: Food | I10: =50+120+90+115 -> 375 | J10: Green
C11: =50+70+60 -> 180 | F11: =21.19+22 -> 43.19 | G11: Gas | I11: 9.99 | J11: Spotify | Z11: Cash | AB11: Bank
C12: 500 | D12: Mom | F12: 10 | G12: Haircut | I12: 6.99 | J12: Disney Plus | Q12: =Q6+P14 -> 8.65 | R12: Balance | U12: =AB12+Z12 -> 85.92 | W12: =U12-U6 -> -18.72 | X12: =W12/30 -> -0.624 | Y12: Wallet | Z12: 31 | AA12: Checking | AB12: 54.92
B13: 44001 | C13: 645.2 | D13: UCO | F13: 712.86 | G13: UCO | I13: 15.4 | J13: EVE Online | Q13: =Q7+SUM(L10:L13) -> 645.96 | R13: Savings | U13: =AB13+Z13+Z14 -> 497.96 | W13: =U13-U7 -> -148 | X13: =W13/30 -> -4.9333333 | Y13: Drawer | Z13: =140+144 -> 284 | AA13: Savings | AB13: 101.96
O14: =P14/30 -> -3.1996667 | P14: =SUM(C9:C14)-SUM(F9:F14)-SUM(I9:I14) -> -95.99 | Q14: =Q12+Q13 -> 654.61 | R14: Total | U14: =AB12+AB13+Z12+Z13+Z14 -> 583.88 | W14: =U14-U8 -> -166.72 | X14: =W14/30 -> -5.5573333 | Y14: Coins | Z14: 112
A15: êêê | B15: 44013
C16: =75+60 -> 135 | F16: =9+10+9+7+10+15+9+9+10+9+10+6+8.47+21.7+10+8+10+6+10+10+11+38.71+6+9.48+10.79+7 -> 280.15 | G16: Food | I16: =240+75+90+90+110 -> 605 | J16: Green | L16: -240
C17: 200 | D17: Mom | F17: =26.02+26.14 -> 52.16 | G17: Gas | I17: 9.99 | J17: Spotify | L17: 170 | Z17: Cash | AB17: Bank
B18: 44014 | C18: 645.2 | D18: UCO | F18: 300 | G18: Mom | I18: 6.99 | J18: Disney Plus | L18: -100 | O18: =P18/31 -> 10.449032 | P18: =SUM(C16:C19)-SUM(F16:F19)-SUM(I16:I19)-SUM(L16:L19) -> 323.92 | Q18: =Q12+P18 -> 332.57 | R18: Balance | U18: =AB18+Z18 -> 367.95 | W18: =U18-U12 -> 282.03 | X18: =W18/31 -> 9.0977419 | Y18: Wallet | Z18: 216 | AA18: Checking | AB18: 151.95
B19: 44043 | C19: 629.01 | D19: UCO | I19: 1 | J19: Xbox Live | L19: 200 | O19: =P19/31 -> 0.96774194 | P19: =SUM(L15:L20) -> 30 | Q19: =Q13+SUM(L16:L19) -> 675.96 | R19: Savings | U19: =AB19+Z19+Z20 -> 562.96 | W19: =U19-U13 -> 65 | X19: =W19/31 -> 2.0967742 | Y19: Drawer | Z19: =344 -> 344 | AA19: Savings | AB19: 101.96
O20: =P20/31 -> 11.416774 | P20: =SUM(C15:C20)-SUM(F15:F20)-SUM(I15:I20) -> 353.92 | Q20: =Q14+P20 -> 1008.53 | R20: Total | U20: =AB18+AB19+Z18+Z19+Z20 -> 930.91 | W20: =U20-U14 -> 347.03 | X20: =W20/31 -> 11.194516 | Y20: Coins | Z20: 117
A21: êêê | B21: August
F22: =8+32.55+7.8+6+9.48+9+6+7+20+40+4.55+10+5+12+8.47+5+10+5+10+8+21.7+5+5+10+8.47+5+9+6+22+9+10 -> 335.02 | G22: Food | I22: =90+90+35+80+200 -> 495 | J22: Green | L22: -100
F23: =24.95+8.06+26.8 -> 59.81 | G23: Gas | I23: 19.99 | J23: Call of Duty | L23: -100
F24: 10 | G24: Haircut | I24: 9.99 | J24: Spotify
F25: 50 | G25: Caitlin's Birthday | I25: 19.99 | J25: Fall Guys | Z25: Cash | AB25: Bank
C26: =60+60 -> 120 | F26: 19.99 | G26: Adobe Creative | I26: 14.99 | J26: Xbox Live | O26: =P26/31 -> -10.221613 | P26: =SUM(C24:C27)-SUM(F22:F27)-SUM(I22:I27)-SUM(L22:L27) -> -316.87 | Q26: =Q18+P26 -> 15.7 | R26: Balance | U26: =Z26+AB26 -> 51.08 | W26: =U26-U18 -> -316.87 | X26: =W26/31 -> -10.221613 | Y26: Wallet | Z26: 39 | AA26: Checking | AB26: 12.08
B27: 44057 | C27: 404.9 | D27: UCO | I27: 6.99 | J27: Disney Plus | O27: =P27/31 -> -6.4516129 | P27: =SUM(L22:L27) -> -200 | Q27: =Q19+SUM(L22:L27) -> 475.96 | R27: Savings | U27: =Z27+Z28+AB27 -> 370.96 | W27: =U27-U19 -> -192 | X27: =W27/31 -> -6.1935484 | Y27: Drawer | Z27: 144 | AA27: Savings | AB27: 101.96
O28: =P28/31 -> -16.673226 | P28: =SUM(C24:C27)-SUM(F22:F27)-SUM(I22:I27) -> -516.87 | Q28: =Q20+P28 -> 491.66 | R28: Total | U28: =U26+U27 -> 422.04 | W28: =U28-U20 -> -508.87 | X28: =W28/31 -> -16.415161 | Y28: Coins | Z28: 125
A29: êêê | B29: September
F30: =5+9+5+8.57+9+9+6+10+6+9.47+7.47+10+9+6+2+9+21.7+7+9+9+11+9+9+9+9+6+9+17+6+9+8.9+8+36.95+8.9+9+7.81+10 -> 350.77 | G30: Food | I30: =40+115+95+60+200+25 -> 535 | J30: Green | L30: -70
F31: =26.49+9.97+26.54+25.49 -> 88.49 | G31: Gas | I31: 9.99 | J31: Spotify | L31: -40
C32: =30+60+60 -> 150 | F32: 10 | G32: Haircut | I32: 0.99 | J32: KRON App | L32: 15
C33: 100 | D33: Mom | F33: 1463.51 | G33: UCO | I33: 6.99 | J33: Disney Plus | L33: 2980
B34: 44085 | C34: 113.8 | D34: UCO | F34: 300 | G34: Mom | I34: 93.82 | J34: External HDD
B35: 44088 | C35: 8410 | D35: FAFSA Loan | F35: 2400 | G35: VW | I35: 19.99 | J35: Masks | Z35: Cash | AB35: Bank
B36: 44092 | C36: 180 | D36: Papa | F36: 290 | G36: VW | I36: 19.99 | J36: Adobe Creative | O36: =P36/30 -> 19.635333 | P36: =SUM(C30:C37)-SUM(F30:F37)-SUM(I30:I37)-SUM(L30:L37) -> 589.06 | Q36: =Q26+P38-SUM(L30:L37) -> 604.76 | R36: Balance | U36: =Z36+AB36 -> 629.59 | W36: =U36-U26 -> 578.51 | X36: =W36/30 -> 19.283667 | Y36: Wallet | Z36: 297 | AA36: Checking | AB36: 332.59
B37: 44099 | C37: 113.8 | D37: UCO | F37: 4 | G37: Notebook | O37: =P37/30 -> 96.166667 | P37: =SUM(L30:L37) -> 2885 | Q37: =Q27+SUM(L30:L37) -> 3360.96 | R37: Savings | U37: =Z37+Z38+AB37 -> 3260.99 | W37: =U37-U27 -> 2890.03 | X37: =W37/30 -> 96.334333 | Y37: Drawer | Z37: 124 | AA37: Savings | AB37: 3001.99
O38: =P38/30 -> 115.802 | P38: =SUM(C30:C37)-SUM(F30:F37)-SUM(I29:I38) -> 3474.06 | Q38: =Q36+Q37 -> 3965.72 | R38: Total | U38: =U36+U37 -> 3890.58 | W38: =U38-U28 -> 3468.54 | X38: =W38/30 -> 115.618 | Y38: Coins | Z38: 135
A39: êêê | B39: October
F40: =9+2+9+15+7.81+9+10+12+5+9+27+6+9+9+9+10+7.81+10+36.66+8+11+9+8+6+7+5+9+9+5 -> 289.28 | G40: Food | I40: =65+80+220 -> 365 | J40: Green
F41: =22.05+23.51 -> 45.56 | G41: Gas | I41: 39.99 | J41: SW Squadrons
F42: 24 | G42: AIP | I42: 9.99 | J42: Spotify
...

Sheet Data Analysis
D2: Economy | S2: Parameters | AG2: Signal Dynamics | AR2: Accuracy, Precision, Errors, and Differences | AZ2: Exercise Days per Month
D3: Model | K3: Actual | S3: Predictive | Z3: Model | AG3: Velocity (Δ$/Mo) | AM3: Acceleration (ΔVelocity/Mo) | AR3: Model Deviation from Actual | AU3: Percent Error (Accuracy) | AW3: Percent Diff (Precision) | BP3: Meaningless signal?
B4: Month | C4: Income | D4: Total | E4: Balance | F4: Savings | G4: Savings 2 | H4: Market | I4: Bitcoin | J4: Stocks | K4: Total | L4: Balance | M4: Savings A | N4: Savings B | O4: Bitcoin | P4: Stocks | Q4: Market | R4: Spending | S4: Gas | T4: Grub | U4: Green | V4: Other | W4: Necessary | X4: Unnecessary | Y4: Total | Z4: Gas | AA4: Grub | AB4: Green | AC4: Other | AD4: Necessary | AE4: Unnecessary | AF4: Spending | AG4: Model 1 | AH4: Model 2 | AI4: Actual 1 | AJ4: Actual 2 | AK4: Model Dev | AL4: Actual Dev | AM4: Model 1 | AN4: Model 2 | AO4: Actual | AP4: Model Dev | AQ4: Net Dev | AR4: of $ | AS4: of Δ$1 | AT4: of Δ$2 | AU4: % Error of $ | AV4: % Error of Δ$ | AW4: % Diff of $ | AX4: % Diff of Δ$
B5: 43952 | C5: =SUM(Data!C4:C7) -> 814.17 | D5: =Data!Q8 -> 750.6 | E5: =Data!Q6 -> 104.64 | F5: =Data!Q7 -> 645.96 | K5: =Data!U8 -> 750.6 | L5: =Data!U6 -> 104.64 | N5: =Data!U7 -> 645.96 | S5: 50 | T5: 250 | U5: 240 | V5: 50 | Z5: =Data!F6 -> 120 | AA5: =Data!F5 -> 240 | AB5: =Data!I5 -> 205 | AC5: =SUM(Data!I6:I7) -> 16.98 | AD5: =SUM(Data!F5:F7) -> 1072.86 | AE5: =SUM(Data!I5:I7) -> 221.98 | AF5: =SUM(AD5:AE5) -> 1294.84 | AG5: =C5-AF5 -> -480.67 | AR5: =K5-D5 -> 0 | AU5: =ABS(AR5/K5) -> 0 | AW5: =ABS(AR5/AVERAGE(K5,D5)) -> 0 | BP5: =ABS((AR6-AS6)/((ABS(AR6)+ABS(AS6))/2))/10 -> 1.6073355e-16
B6: 43983 | C6: =SUM(Data!C10:C13) -> 1325.2 | D6: =Data!Q14 -> 654.61 | E6: =Data!Q12 -> 8.65 | F6: =Data!Q13 -> 645.96 | K6: =Data!U14 -> 583.88 | L6: =Data!U12 -> 85.92 | N6: =Data!U13 -> 497.96 | R6: =K5-K6+C6 -> 1491.92 | S6: 50 | T6: 250 | U6: 240 | V6: 50 | Z6: =Data!F11 -> 43.19 | AA6: =Data!F10 -> 247.76 | AB6: =Data!I10-Data!C11 -> 195 | AC6: =SUM(Data!I11:I13) -> 32.38 | AD6: =SUM(Data!F10:F13) -> 1013.81 | AE6: =SUM(Data!I10:I13) -> 407.38 | AF6: =SUM(AD6:AE6) -> 1421.19 | AG6: =C6-AF6 -> -95.99 | AH6: =D6-D5 -> -95.99 | AI6: =C6-R6 -> -166.72 | AJ6: =K6-K5 -> -166.72 | AK6: =AG6-AH6 -> -2.2737368e-13 | AL6: =AI6-AJ6 -> 0 | AR6: =K6-D6 -> -70.73 | AS6: =AI6-AG6 -> -70.73 | AT6: =AJ6-AH6 -> -70.73 | AU6: =ABS(AR6/K6) -> 0.12113791 | AV6: =ABS(AS6/AI6) -> 0.42424424 | AW6: =ABS(AR6/AVERAGE(K6,D6)) -> 0.11421974 | AX6: =ABS((AG6-AH6)/AVERAGE(AG6,AH6)) -> 2.3687225e-15 | BP6: =ABS((AR7-AS7)/((ABS(AR7)+ABS(AS7))/2))/10 -> 0.16738847
B7: 44013 | C7: =SUM(Data!C16:C19) -> 1609.21 | D7: =Data!Q20 -> 1008.53 | E7: =Data!Q18 -> 332.57 | F7: =Data!Q19 -> 675.96 | K7: =Data!U20 -> 930.91 | L7: =Data!U18 -> 367.95 | N7: =Data!U19 -> 562.96 | R7: =K6-K7+C7 -> 1262.18 | S7: 50 | T7: 250 | U7: 250 | V7: 50 | Z7: =Data!F17 -> 52.16 | AA7: =Data!F16 -> 280.15 | AB7: =Data!I16-Data!C16 -> 470 | AC7: =SUM(Data!I17:I19) -> 17.98 | AD7: =SUM(Data!F16:F18) -> 632.31 | AE7: =SUM(Data!I16:I19) -> 622.98 | AF7: =SUM(AD7:AE7) -> 1255.29 | AG7: =C7-AF7 -> 353.92 | AH7: =D7-D6 -> 353.92 | AI7: =C7-R7 -> 347.03 | AJ7: =K7-K6 -> 347.03 | AK7: =AG7-AH7 -> 0 | AL7: =AI7-AJ7 -> 0 | AM7: =AG7-AG6 -> 449.91 | AN7: =AH7-AH6 -> 449.91 | AO7: =AJ7-AJ6 -> 513.75 | AP7: =AN7-AM7 -> 0 | AQ7: =AO7-AN7 -> 63.84 | AR7: =K7-D7 -> -77.62 | AS7: =AI7-AG7 -> -6.89 | AT7: =AJ7-AH7 -> -6.89 | AU7: =ABS(AR7/K7) -> 0.083380778 | AV7: =ABS(AS7/AI7) -> 0.019854191 | AW7: =ABS(AR7/AVERAGE(K7,D7)) -> 0.080043724 | AX7: =ABS((AG7-AH7)/AVERAGE(AG7,AH7)) -> 3.2122185e-16 | BP7: =ABS((AR8-AS8)/((ABS(AR8)+ABS(AS8))/2))/10 -> 0.2
B8: 44044 | C8: =SUM(Data!C22:C27) -> 524.9 | D8: =Data!Q28 -> 491.66 | E8: =Data!Q26 -> 15.7 | F8: =Data!Q27 -> 475.96 | K8: =Data!U28 -> 422.04 | L8: =Data!U26 -> 51.08 | N8: =Data!U27 -> 370.96 | R8: =K7-K8+C8 -> 1033.77 | S8: 60 | T8: 300 | U8: 300 | V8: 50 | Z8: =Data!F23 -> 59.81 | AA8: =Data!F22 -> 335.02 | AB8: =Data!I22-Data!C26 -> 375 | AC8: =SUM(Data!I23:I27) -> 71.95 | AD8: =SUM(Data!F22:F26) -> 474.82 | AE8: =SUM(Data!I22:I27) -> 566.95 | AF8: =SUM(AD8:AE8) -> 1041.77 | AG8: =C8-AF8 -> -516.87 | AH8: =D8-D7 -> -516.87 | AI8: =C8-R8 -> -508.87 | AJ8: =K8-K7 -> -508.87 | AK8: =AG8-AH8 -> 0 | AL8: =AI8-AJ8 -> 0 | AM8: =AG8-AG7 -> -870.79 | AN8: =AH8-AH7 -> -870.79 | AO8: =AJ8-AJ7 -> -855.9 | AP8: =AN8-AM8 -> 0 | AQ8: =AO8-AN8 -> 14.89 | AR8: =K8-D8 -> -69.62 | AS8: =AI8-AG8 -> 8 | AT8: =AJ8-AH8 -> 8 | AU8: =ABS(AR8/K8) -> 0.16496067 | AV8: =ABS(AS8/AI8) -> 0.015721108 | AW8: =ABS(AR8/AVERAGE(K8,D8)) -> 0.15239138 | AX8: =ABS((AG8-AH8)/AVERAGE(AG8,AH8)) -> 2.1995248e-16 | BP8: =ABS((AR9-AS9)/((ABS(AR9)+ABS(AS9))/2))/10 -> 0.17262584
B9: 44075 | C9: =SUM(Data!C32:C37) -> 9067.6 | D9: =Data!Q38 -> 3965.72 | E9: =Data!Q36 -> 604.76 | F9: =Data!Q37 -> 3360.96 | K9: =Data!U38 -> 3890.58 | L9: =Data!U36 -> 629.59 | N9: =Data!U37 -> 3260.99 | R9: =K8-K9+C9 -> 5599.06 | S9: 60 | T9: 300 | U9: 300 | V9: 50 | Z9: =Data!F31 -> 88.49 | AA9: =Data!F30 -> 350.77 | AB9: =Data!I30-Data!C32 -> 385 | AC9: =SUM(Data!I31:I36) -> 151.77 | AD9: =SUM(Data!F30:F37) -> 4906.77 | AE9: =SUM(Data!I30:I36) -> 686.77 | AF9: =SUM(AD9:AE9) -> 5593.54 | AG9: =C9-AF9 -> 3474.06 | AH9: =D9-D8 -> 3474.06 | AI9: =C9-R9 -> 3468.54 | AJ9: =K9-K8 -> 3468.54 | AK9: =AG9-AH9 -> 0 | AL9: =AI9-AJ9 -> 0 | AM9: =AG9-AG8 -> 3990.93 | AN9: =AH9-AH8 -> 3990.93 | AO9: =AJ9-AJ8 -> 3977.41 | AP9: =AN9-AM9 -> 0 | AQ9: =AO9-AN9 -> -13.52 | AR9: =K9-D9 -> -75.14 | AS9: =AI9-AG9 -> -5.52 | AT9: =AJ9-AH9 -> -5.52 | AU9: =ABS(AR9/K9) -> 0.019313316 | AV9: =ABS(AS9/AI9) -> 0.0015914477 | AW9: =ABS(AR9/AVERAGE(K9,D9)) -> 0.019128597 | AX9: =ABS((AG9-AH9)/AVERAGE(AG9,AH9)) -> 1.3089796e-16 | BP9: =ABS((AR10-AS10)/((ABS(AR10)+ABS(AS10))/2))/10 -> 0.2
B10: 44105 | C10: =SUM(Data!C40:C47) -> 995.74 | D10: =Data!Q48 -> 3870.17 | E10: =Data!Q46 -> 509.21 | F10: =Data!Q47 -> 3360.96 | K10: =Data!U48 -> 3800.58 | L10: =Data!U46 -> 533.54 | N10: =Data!U47 -> 3267.04 | R10: =K9-K10+C10 -> 1085.74 | S10: 60 | T10: 350 | U10: 300 | V10: 50 | Z10: =Data!F41 -> 45.56 | AA10: =Data!F40 -> 289.28 | AB10: =Data!I40-Data!C44 -> 235 | AC10: =SUM(Data!I41:I45) -> 77.95 | AD10: =SUM(Data!F40:F47) -> 648.34 | AE10: =SUM(Data!I40:I45) -> 442.95 | AF10: =SUM(AD10:AE10) -> 1091.29 | AG10: =C10-AF10 -> -95.55 | AH10: =D10-D9 -> -95.55 | AI10: =C10-R10 -> -90 | AJ10: =K10-K9 -> -90 | AK10: =AG10-AH10 -> -2.2737368e-13 | AL10: =AI10-AJ10 -> 0 | AM10: =AG10-AG9 -> -3569.61 | AN10: =AH10-AH9 -> -3569.61 | AO10: =AJ10-AJ9 -> -3558.54 | AP10: =AN10-AM10 -> 0 | AQ10: =AO10-AN10 -> 11.07 | AR10: =K10-D10 -> -69.59 | AS10: =AI10-AG10 -> 5.55 | AT10: =AJ10-AH10 -> 5.55 | AU10: =ABS(AR10/K10) -> 0.018310363 | AV10: =ABS(AS10/AI10) -> 0.061666667 | AW10: =ABS(AR10/AVERAGE(K10,D10)) -> 0.018144249 | AX10: =ABS((AG10-AH10)/AVERAGE(AG10,AH10)) -> 2.3796303e-15 | BP10: =ABS((AR11-AS11)/((ABS(AR11)+ABS(AS11))/2))/10 -> 0.2
B11: 44136 | C11: =SUM(Data!C50:C54) -> 458.92 | D11: =Data!Q55 -> 3437.11 | E11: =Data!Q53 -> 476.15 | F11: =Data!Q54 -> 2960.96 | K11: =Data!U55 -> 3373.57 | L11: =Data!U53 -> 500.48 | N11: =Data!U54 -> 2873.09 | R11: =K10-K11+C11 -> 885.93 | S11: 60 | T11: 350 | U11: 300 | V11: 50 | Z11: =Data!F51 -> 48.47 | AA11: =Data!F50 -> 280.55 | AB11: =Data!I50-Data!C52 -> 340 | AC11: =SUM(Data!I51:I54) -> 37.96 | AD11: =SUM(Data!F50:F53) -> 494.02 | AE11: =SUM(Data!I50:I54) -> 397.96 | AF11: =SUM(AD11:AE11) -> 891.98 | AG11: =C11-AF11 -> -433.06 | AH11: =D11-D10 -> -433.06 | AI11: =C11-R11 -> -427.01 | AJ11: =K11-K10 -> -427.01 | AK11: =AG11-AH11 -> 0 | AL11: =AI11-AJ11 -> 0 | AM11: =AG11-AG10 -> -337.51 | AN11: =AH11-AH10 -> -337.51 | AO11: =AJ11-AJ10 -> -337.01 | AP11: =AN11-AM11 -> -6.2527761e-13 | AQ11: =AO11-AN11 -> 0.5 | AR11: =K11-D11 -> -63.54 | AS11: =AI11-AG11 -> 6.05 | AT11: =AJ11-AH11 -> 6.05 | AU11: =ABS(AR11/K11) -> 0.018834647 | AV11: =ABS(AS11/AI11) -> 0.014168286 | AW11: =ABS(AR11/AVERAGE(K11,D11)) -> 0.01865893 | AX11: =ABS((AG11-AH11)/AVERAGE(AG11,AH11)) -> 9.1881941e-16 | BP11: =ABS((AR12-AS12)/((ABS(AR12)+ABS(AS12))/2))/10 -> 0.2
B12: 44166 | C12: =SUM(Data!C57:C65) -> 703.92 | D12: =Data!Q66 -> 2359.06 | E12: =Data!Q64 -> 218.1 | F12: =Data!Q65 -> 2140.96 | K12: =Data!U66 -> 2303.56 | L12: =Data!U64 -> 244.43 | N12: =Data!U65 -> 2059.13 | R12: =K11-K12+C12 -> 1773.93 | S12: 60 | T12: 350 | U12: 300 | V12: 100 | Z12: =Data!F58 -> 82.66 | AA12: =Data!F57 -> 269 | AB12: =Data!I57-Data!C62 -> 590 | AC12: =SUM(Data!I58:I60) -> 36.97 | AD12: =SUM(Data!F57:F65) -> 1115 | AE12: =SUM(Data!I57:I60) -> 666.97 | AF12: =SUM(AD12:AE12) -> 1781.97 | AG12: =C12-AF12 -> -1078.05 | AH12: =D12-D11 -> -1078.05 | AI12: =C12-R12 -> -1070.01 | AJ12: =K12-K11 -> -1070.01 | AK12: =AG12-AH12 -> 0 | AL12: =AI12-AJ12 -> 0 | AM12: =AG12-AG11 -> -644.99 | AN12: =AH12-AH11 -> -644.99 | AO12: =AJ12-AJ11 -> -643 | AP12: =AN12-AM12 -> 0 | AQ12: =AO12-AN12 -> 1.99 | AR12: =K12-D12 -> -55.5 | AS12: =AI12-AG12 -> 8.04 | AT12: =AJ12-AH12 -> 8.04 | AU12: =ABS(AR12/K12) -> 0.024093143 | AV12: =ABS(AS12/AI12) -> 0.0075139485 | AW12: =ABS(AR12/AVERAGE(K12,D12)) -> 0.023806358 | AX12: =ABS((AG12-AH12)/AVERAGE(AG12,AH12)) -> 2.1091199e-16 | BP12: =ABS((AR13-AS13)/((ABS(AR13)+ABS(AS13))/2))/10 -> 0.15985023
B13: 44197 | C13: =SUM(Data!C68:C73) -> 720 | D13: =Data!Q74 -> 1667.12 | E13: =Data!Q72 -> 126.16 | F13: =Data!Q73 -> 1540.96 | K13: =Data!U74 -> 1604.65 | L13: =Data!U72 -> 127.49 | N13: =Data!U73 -> 1477.16 | R13: =K12-K13+C13 -> 1418.91 | S13: 60 | T13: 350 | U13: 250 | V13: 50 | Z13: =Data!F71 -> 28.43 | AA13: =Data!F68 -> 249.27 | AB13: =Data!I68-Data!C72 -> 655 | AC13: =SUM(Data!I69:I73) -> 105.24 | AD13: =SUM(Data!F68:F73) -> 531.7 | AE13: =SUM(Data!I68:I73) -> 880.24 | AF13: =SUM(AD13:AE13) -> 1411.94 | AG13: =C13-AF13 -> -691.94 | AH13: =D13-D12 -> -691.94 | AI13: =C13-R13 -> -698.91 | AJ13: =K13-K12 -> -698.91 | AK13: =AG13-AH13 -> 0 | AL13: =AI13-AJ13 -> 0 | AM13: =AG13-AG12 -> 386.11 | AN13: =AH13-AH12 -> 386.11 | AO13: =AJ13-AJ12 -> 371.1 | AP13: =AN13-AM13 -> 0 | AQ13: =AO13-AN13 -> -15.01 | AR13: =K13-D13 -> -62.47 | AS13: =AI13-AG13 -> -6.97 | AT13: =AJ13-AH13 -> -6.97 | AU13: =ABS(AR13/K13) -> 0.038930608 | AV13: =ABS(AS13/AI13) -> 0.0099726717 | AW13: =ABS(AR13/AVERAGE(K13,D13)) -> 0.038187281 | AX13: =ABS((AG13-AH13)/AVERAGE(AG13,AH13)) -> 0 | BP13: =ABS((AR14-AS14)/((ABS(AR14)+ABS(AS14))/2))/10 -> 0.2
B14: 44228 | C14: =SUM(Data!C76:C81) -> 120 | D14: =Data!Q82 -> 698.06 | E14: =Data!Q80 -> 57.1 | F14: =Data!Q81 -> 640.96 | K14: =Data!U82 -> 649.4 | L14: =Data!U80 -> 64.23 | N14: =Data!U81 -> 585.17 | R14: =K13-K14+C14 -> 1075.25 | S14: 60 | T14: 250 | U14: 300 | V14: 60 | Z14: =Data!F77 -> 55.98 | AA14: =Data!F76 -> 218.02 | AB14: =Data!I76-Data!C81 -> 480 | AC14: =SUM(Data!I77:I81) -> 52.11 | AD14: =SUM(Data!F76:F80) -> 436.95 | AE14: =SUM(Data!I76:I81) -> 652.11 | AF14: =SUM(AD14:AE14) -> 1089.06 | AG14: =C14-AF14 -> -969.06 | AH14: =D14-D13 -> -969.06 | AI14: =C14-R14 -> -955.25 | AJ14: =K14-K13 -> -955.25 | AK14: =AG14-AH14 -> 0 | AL14: =AI14-AJ14 -> 0 | AM14: =AG14-AG13 -> -277.12 | AN14: =AH14-AH13 -> -277.12 | AO14: =AJ14-AJ13 -> -256.34 | AP14: =AN14-AM14 -> 0 | AQ14: =AO14-AN14 -> 20.78 | AR14: =K14-D14 -> -48.66 | AS14: =AI14-AG14 -> 13.81 | AT14: =AJ14-AH14 -> 13.81 | AU14: =ABS(AR14/K14) -> 0.074930705 | AV14: =ABS(AS14/AI14) -> 0.014456948 | AW14: =ABS(AR14/AVERAGE(K14,D14)) -> 0.072224778 | AX14: =ABS((AG14-AH14)/AVERAGE(AG14,AH14)) -> 0 | BP14: =ABS((AR15-AS15)/((ABS(AR15)+ABS(AS15))/2))/10 -> 0.19225603
B15: 44256 | C15: =SUM(Data!C84:C90) -> 1507.95 | D15: =Data!Q91 -> 1048.52 | E15: =Data!Q89 -> 457.56 | F15: =Data!Q90 -> 590.96 | K15: =Data!U91 -> 998.88 | L15: =Data!U89 -> 459.71 | N15: =Data!U90 -> 539.17 | R15: =K14-K15+C15 -> 1158.47 | S15: 60 | T15: 300 | U15: 150 | V15: 60 | Z15: =Data!F85 -> 53.58 | AA15: =Data!F84 -> 195.15 | AB15: =Data!I85 -> 300 | AC15: =Data!I84+SUM(Data!I86:I90) -> 453.76 | AD15: =SUM(Data!F84:F87) -> 403.73 | AE15: =SUM(Data!I84:I90) -> 753.76 | AF15: =SUM(AD15:AE15) -> 1157.49 | AG15: =C15-AF15 -> 350.46 | AH15: =D15-D14 -> 350.46 | AI15: =C15-R15 -> 349.48 | AJ15: =K15-K14 -> 349.48 | AK15: =AG15-AH15 -> 0 | AL15: =AI15-AJ15 -> 0 | AM15: =AG15-AG14 -> 1319.52 | AN15: =AH15-AH14 -> 1319.52 | AO15: =AJ15-AJ14 -> 1304.73 | AP15: =AN15-AM15 -> 0 | AQ15: =AO15-AN15 -> -14.79 | AR15: =K15-D15 -> -49.64 | AS15: =AI15-AG15 -> -0.98 | AT15: =AJ15-AH15 -> -0.98 | AU15: =ABS(AR15/K15) -> 0.049695659 | AV15: =ABS(AS15/AI15) -> 0.0028041662 | AW15: =ABS(AR15/AVERAGE(K15,D15)) -> 0.048490769 | AX15: =ABS((AG15-AH15)/AVERAGE(AG15,AH15)) -> 0 | BP15: =ABS((AR16-AS16)/((ABS(AR16)+ABS(AS16))/2))/10 -> 0.2
B16: 44287 | C16: =SUM(Data!C93:C99) -> 300 | D16: =Data!Q100 -> 426.57 | E16: =Data!Q98 -> 156.61 | F16: =Data!Q99 -> 269.96 | K16: =Data!U100 -> 400.4 | L16: =Data!U98 -> 174.23 | N16: =Data!U99 -> 226.17 | O16: =Data!AD99 -> 18 | R16: =K15-K16+C16 -> 898.48 | S16: 60 | T16: 250 | U16: 200 | V16: 60 | Z16: =Data!F94 -> 70.93 | AA16: =Data!F93 -> 250.29 | AB16: =Data!I93 -> 305 | AC16: =SUM(Data!I94:I99) -> 92.73 | AD16: =SUM(Data!F93:F98) -> 524.22 | AE16: =SUM(Data!I93:I99) -> 397.73 | AF16: =SUM(AD16:AE16) -> 921.95 | AG16: =C16-AF16 -> -621.95 | AH16: =D16-D15 -> -621.95 | AI16: =C16-R16 -> -598.48 | AJ16: =K16-K15 -> -598.48 | AK16: =AG16-AH16 -> 0 | AL16: =AI16-AJ16 -> 0 | AM16: =AG16-AG15 -> -972.41 | AN16: =AH16-AH15 -> -972.41 | AO16: =AJ16-AJ15 -> -947.96 | AP16: =AN16-AM16 -> 0 | AQ16: =AO16-AN16 -> 24.45 | AR16: =K16-D16 -> -26.17 | AS16: =AI16-AG16 -> 23.47 | AT16: =AJ16-AH16 -> 23.47 | AU16: =ABS(AR16/K16) -> 0.06535964 | AV16: =ABS(AS16/AI16) -> 0.039216014 | AW16: =ABS(AR16/AVERAGE(K16,D16)) -> 0.063291292 | AX16: =ABS((AG16-AH16)/AVERAGE(AG16,AH16)) -> 0 | BP16: =ABS((AR17-AS17)/((ABS(AR17)+ABS(AS17))/2))/10 -> 0.2
B17: 44317 | C17: =SUM(Data!C102:C109) -> 3513.28 | D17: =Data!Q110 -> 2958.95 | E17: =Data!Q108 -> 868.99 | F17: =Data!Q109 -> 2089.96 | K17: =Data!U110 -> 2941.73 | L17: =Data!U108 -> 889.55 | N17: =Data!U109 -> 2052.18 | O17: =Data!AD109 -> 36.69 | R17: =K16-K17+C17 -> 971.95 | S17: 100 | T17: 250 | U17: 200 | V17: 60 | Z17: =Data!F103 -> 145.55 | AA17: =Data!F102 -> 263.29 | AB17: =Data!I102 -> 320 | AC17: =SUM(Data!I103:I108) -> 87.06 | AD17: =SUM(Data!F102:F107) -> 573.84 | AE17: =SUM(Data!I102:I108) -> 407.06 | AF17: =SUM(AD17:AE17) -> 980.9 | AG17: =C17-AF17 -> 2532.38 | AH17: =D17-D16 -> 2532.38 | AI17: =C17-R17 -> 2541.33 | AJ17: =K17-K16 -> 2541.33 | AK17: =AG17-AH17 -> 0 | AL17: =AI17-AJ17 -> 0 | AM17: =AG17-AG16 -> 3154.33 | AN17: =AH17-AH16 -> 3154.33 | AO17: =AJ17-AJ16 -> 3139.81 | AP17: =AN17-AM17 -> 0 | AQ17: =AO17-AN17 -> -14.52 | AR17: =K17-D17 -> -17.22 | AS17: =AI17-AG17 -> 8.95 | AT17: =AJ17-AH17 -> 8.95 | AU17: =ABS(AR17/K17) -> 0.0058536983 | AV17: =ABS(AS17/AI17) -> 0.003521778 | AW17: =ABS(AR17/AVERAGE(K17,D17)) -> 0.0058366154 | AX17: =ABS((AG17-AH17)/AVERAGE(AG17,AH17)) -> 0 | BP17: =ABS((AR18-AS18)/((ABS(AR18)+ABS(AS18))/2))/10 -> 0.13920776
B18: 44348 | C18: =SUM(Data!C112:C118) -> 2925 | D18: =Data!Q119 -> 3999.29 | E18: =Data!Q117 -> 1089.33 | F18: =Data!Q118 -> 2909.96 | K18: =Data!U119 -> 3978.31 | L18: =Data!U117 -> 1100.09 | N18: =Data!U118 -> 2878.22 | O18: =Data!AD118 -> 46.39 | R18: =K17-K18+C18 -> 1888.42 | S18: 160 | T18: 300 | U18: 400 | V18: 80 | Z18: =Data!F113 -> 160.44 | AA18: =Data!F112 -> 307.92 | AB18: =Data!I112 -> 510 | AC18: =SUM(Data!I113:I118) -> 195.07 | AD18: =SUM(Data!F112:F117) -> 1179.59 | AE18: =SUM(Data!I112:I118) -> 705.07 | AF18: =SUM(AD18:AE18) -> 1884.66 | AG18: =C18-AF18 -> 1040.34 | AH18: =D18-D17 -> 1040.34 | AI18: =C18-R18 -> 1036.58 | AJ18: =K18-K17 -> 1036.58 | AK18: =AG18-AH18 -> 0 | AL18: =AI18-AJ18 -> 0 | AM18: =AG18-AG17 -> -1492.04 | AN18: =AH18-AH17 -> -1492.04 | AO18: =AJ18-AJ17 -> -1504.75 | AP18: =AN18-AM18 -> 0 | AQ18: =AO18-AN18 -> -12.71 | AR18: =K18-D18 -> -20.98 | AS18: =AI18-AG18 -> -3.76 | AT18: =AJ18-AH18 -> -3.76 | AU18: =ABS(AR18/K18) -> 0.0052735961 | AV18: =ABS(AS18/AI18) -> 0.0036273129 | AW18: =ABS(AR18/AVERAGE(K18,D18)) -> 0.0052597272 | AX18: =ABS((AG18-AH18)/AVERAGE(AG18,AH18)) -> 2.1855708e-16 | BP18: =ABS((AR19-AS19)/((ABS(AR19)+ABS(AS19))/2))/10 -> 0.19372114
B19: 44378 | C19: =SUM(Data!C121:C125) -> 3965 | D19: =Data!Q126 -> 6005.93 | E19: =Data!Q123 -> 1095.97 | F19: =Data!Q124 -> 3809.96 | G19: =Data!Q125 -> 1100 | K19: =Data!U126 -> 5984.61 | L19: =Data!U123 -> 1102.34 | M19: =Data!U125 -> 1100 | N19: =Data!U124 -> 3782.27 | O19: =Data!AD124 -> 59.24 | R19: =K18-K19+C19 -> 1958.7 | S19: 160 | T19: 300 | U19: 350 | V19: 80 | Z19: =Data!F122 -> 147.3 | AA19: =Data!F121 -> 290.85 | AB19: =Data!I121 -> 450 | AC19: =SUM(Data!I122:I125) -> 205.21 | AD19: =SUM(Data!F121:F125) -> 1303.15 | AE19: =SUM(Data!I121:I125) -> 655.21 | AF19: =SUM(AD19:AE19) -> 1958.36 | AG19: =C19-AF19 -> 2006.64 | AH19: =D19-D18 -> 2006.64 | AI19: =C19-R19 -> 2006.3 | AJ19: =K19-K18 -> 2006.3 | AK19: =AG19-AH19 -> 0 | AL19: =AI19-AJ19 -> 0 | AM19: =AG19-AG18 -> 966.3 | AN19: =AH19-AH18 -> 966.3 | AO19: =AJ19-AJ18 -> 969.72 | AP19: =AN19-AM19 -> 0 | AQ19: =AO19-AN19 -> 3.42 | AR19: =K19-D19 -> -21.32 | AS19: =AI19-AG19 -> -0.34 | AT19: =AJ19-AH19 -> -0.34 | AU19: =ABS(AR19/K19) -> 0.0035624711 | AV19: =ABS(AS19/AI19) -> 0.00016946618 | AW19: =ABS(AR19/AVERAGE(K19,D19)) -> 0.0035561368 | AX19: =ABS((AG19-AH19)/AVERAGE(AG19,AH19)) -> 2.2662129e-16 | BP19: =ABS((AR20-AS20)/((ABS(AR20)+ABS(AS20))/2))/10 -> 0.026294821
B20: 44409 | C20: =SUM(Data!C129:C134) -> 3065 | D20: =Data!Q135 -> 6793.16 | E20: =Data!Q132 -> 563.2 | F20: =Data!Q133 -> 4229.96 | G20: =Data!Q134 -> 2000 | K20: =Data!U135 -> 6797.52 | L20: =Data!U132 -> 587.19 | M20: =Data!U134 -> 2000 | N20: =Data!U133 -> 4210.33 | O20: =Data!AD133 -> 67.73 | R20: =K19-K20+C20 -> 2252.09 | S20: 160 | T20: 300 | U20: 300 | V20: 120 | Z20: =Data!F129 -> 188.84 | AA20: =Data!F128 -> 305.31 | AB20: =Data!I128 -> 390 | AC20: =SUM(Data!I129:I134) -> 280.21 | AD20: =SUM(Data!F128:F133) -> 1587.56 | AE20: =SUM(Data!I128:I134) -> 670.21 | AF20: =SUM(AD20:AE20) -> 2257.77 | AG20: =C20-AF20 -> 807.23 | AH20: =D20-D19 -> 787.23 | AI20: =C20-R20 -> 812.91 | AJ20: =K20-K19 -> 812.91 | AK20: =AG20-AH20 -> 20 | AL20: =AI20-AJ20 -> 0 | AM20: =AG20-AG19 -> -1199.41 | AN20: =AH20-AH19 -> -1219.41 | AO20: =AJ20-AJ19 -> -1193.39 | AP20: =AN20-AM20 -> -20 | AQ20: =AO20-AN20 -> 26.02 | AR20: =K20-D20 -> 4.36 | AS20: =AI20-AG20 -> 5.68 | AT20: =AJ20-AH20 -> 25.68 | AU20: =ABS(AR20/K20) -> 0.0006414104 | AV20: =ABS(AS20/AI20) -> 0.0069872434 | AW20: =ABS(AR20/AVERAGE(K20,D20)) -> 0.00064161617 | AX20: =ABS((AG20-AH20)/AVERAGE(AG20,AH20)) -> 0.025086863 | BP20: =ABS((AR21-AS21)/((ABS(AR21)+ABS(AS21))/2))/10 -> 0.052466907
B21: 44440 | C21: =SUM(Data!C137:C141) -> 3000 | D21: =Data!Q142 -> 7868.26 | E21: =Data!Q139 -> 638.3 | F21: =Data!Q140 -> 4729.96 | G21: =Data!Q141 -> 2500 | K21: =Data!U142 -> 7862.13 | L21: =Data!U139 -> 643.74 | M21: =Data!U141 -> 2500 | N21: =Data!U140 -> 4718.39 | O21: =Data!AD140 -> 102.59 | R21: =K20-K21+C21 -> 1935.39 | S21: 160 | T21: 300 | U21: 300 | V21: 120 | Z21: =Data!F138 -> 155.61 | AA21: =Data!F137 -> 396.16 | AB21: =Data!I137 -> 338 | AC21: =SUM(Data!I138:I141) -> 30.13 | AD21: =SUM(Data!F137:F141) -> 1556.77 | AE21: =SUM(Data!I137:I141) -> 368.13 | AF21: =SUM(AD21:AE21) -> 1924.9 | AG21: =C21-AF21 -> 1075.1 | AH21: =D21-D20 -> 1075.1 | AI21: =C21-R21 -> 1064.61 | AJ21: =K21-K20 -> 1064.61 | AK21: =AG21-AH21 -> 0 | AL21: =AI21-AJ21 -> 0 | AM21: =AG21-AG20 -> 267.87 | AN21: =AH21-AH20 -> 287.87 | AO21: =AJ21-AJ20 -> 251.7 | AP21: =AN21-AM21 -> 20 | AQ21: =AO21-AN21 -> -36.17 | AR21: =K21-D21 -> -6.13 | AS21: =AI21-AG21 -> -10.49 | AT21: =AJ21-AH21 -> -10.49 | AU21: =ABS(AR21/K21) -> 0.00077968693 | AV21: =ABS(AS21/AI21) -> 0.0098533735 | AW21: =ABS(AR21/AVERAGE(K21,D21)) -> 0.00077938309 | AX21: =ABS((AG21-AH21)/AVERAGE(AG21,AH21)) -> 4.2298144e-16 | BP21: =ABS((AR22-AS22)/((ABS(AR22)+ABS(AS22))/2))/10 -> 0.018405645 | BT21: =6/30 -> 0.2 | BU21: =BT21*1000 -> 200 | BW21: =Health!N32 -> 147.65
B22: 44470 | C22: =SUM(Data!C144:C150) -> 3140 | D22: =Data!Q151 -> 8916.67 | E22: =Data!Q148 -> 666.71 | F22: =Data!Q149 -> 5249.96 | G22: =Data!Q150 -> 3000 | K22: =Data!U151 -> 8946.91 | L22: =Data!Q148 -> 666.71 | M22: =Data!U150 -> 3000 | N22: =Data!U149 -> 5249.46 | O22: =Data!AD149 -> 5.89 | R22: =K21-K22+C22 -> 2055.22 | S22: 160 | T22: 300 | U22: 300 | V22: 200 | Z22: =Data!F145 -> 163.83 | AA22: =Data!F144 -> 273.86 | AB22: =Data!I144 -> 300 | AC22: =SUM(Data!I145:I150) -> 368.9 | AD22: =SUM(Data!F144:F150) -> 1422.69 | AE22: =SUM(Data!I144:I150) -> 668.9 | AF22: =SUM(AD22:AE22) -> 2091.59 | AG22: =C22-AF22 -> 1048.41 | AH22: =D22-D21 -> 1048.41 | AI22: =C22-R22 -> 1084.78 | AJ22: =K22-K21 -> 1084.78 | AK22: =AG22-AH22 -> 0 | AL22: =AI22-AJ22 -> 0 | AM22: =AG22-AG21 -> -26.69 | AN22: =AH22-AH21 -> -26.69 | AO22: =AJ22-AJ21 -> 20.17 | AP22: =AN22-AM22 -> 1.3642421e-12 | AQ22: =AO22-AN22 -> 46.86 | AR22: =K22-D22 -> 30.24 | AS22: =AI22-AG22 -> 36.37 | AT22: =AJ22-AH22 -> 36.37 | AU22: =ABS(AR22/K22) -> 0.0033799379 | AV22: =ABS(AS22/AI22) -> 0.033527536 | AW22: =ABS(AR22/AVERAGE(K22,D22)) -> 0.0033856595 | AX22: =ABS((AG22-AH22)/AVERAGE(AG22,AH22)) -> 8.6749907e-16 | BP22: =ABS((AR23-AS23)/((ABS(AR23)+ABS(AS23))/2))/10 -> 0.13487957 | BT22: =19/31 -> 0.61290323 | BU22: =BT22*1000 -> 612.90323 | BW22: =Health!N33 -> 148.9
B23: 44501 | C23: =SUM(Data!C153:C160) -> 3000 | D23: =Data!Q161 -> 9629.73 | E23: =Data!Q158 -> 379.77 | F23: =Data!Q159 -> 5749.96 | G23: =Data!Q160 -> 3500 | K23: =Data!U161 -> 9667.27 | L23: =Data!U158 -> 409.73 | M23: =Data!U160 -> 3500 | N23: =Data!U159 -> 5757.54 | O23: =Data!AD159 -> 31.89 | R23: =K22-K23+C23 -> 2279.64 | S23: 160 | T23: 300 | U23: 250 | V23: 200 | Z23: =Data!F154 -> 153.47 | AA23: =Data!F153 -> 405.92 | AB23: =Data!I153 -> 260 | AC23: =SUM(Data!I154:I160) -> 171.55 | AD23: =SUM(Data!F153:F160) -> 1855.39 | AE23: =SUM(Data!I153:I160) -> 431.55 | AF23: =SUM(AD23:AE23) -> 2286.94 | AG23: =C23-AF23 -> 713.06 | AH23: =D23-D22 -> 713.06 | AI23: =C23-R23 -> 720.36 | AJ23: =K23-K22 -> 720.36 | AK23: =AG23-AH23 -> 0 | AL23: =AI23-AJ23 -> 0 | AM23: =AG23-AG22 -> -335.35 | AN23: =AH23-AH22 -> -335.35 | AO23: =AJ23-AJ22 -> -364.42 | AP23: =AN23-AM23 -> -1.3642421e-12 | AQ23: =AO23-AN23 -> -29.07 | AR23: =K23-D23 -> 37.54 | AS23: =AI23-AG23 -> 7.3 | AT23: =AJ23-AH23 -> 7.3 | AU23: =ABS(AR23/K23) -> 0.0038832059 | AV23: =ABS(AS23/AI23) -> 0.010133822 | AW23: =ABS(AR23/AVERAGE(K23,D23)) -> 0.0038907602 | AX23: =ABS((AG23-AH23)/AVERAGE(AG23,AH23)) -> 6.3774065e-16 | BP23: =ABS((AR24-AS24)/((ABS(AR24)+ABS(AS24))/2))/10 -> 0.19830956 | BT23: =19/30 -> 0.63333333 | BU23: =BT23*1000 -> 633.33333 | BW23: =Health!N34 -> 152.96
B24: 44531 | C24: =SUM(Data!C163:C171) -> 4870 | D24: =Data!Q172 -> 11743.84 | E24: =Data!Q169 -> 493.88 | F24: =Data!Q170 -> 6749.96 | G24: =Data!Q171 -> 4500 | K24: =Data!U172 -> 11781.54 | L24: =Data!U169 -> 519.91 | M24: =Data!U171 -> 4500 | N24: =Data!U170 -> 6761.63 | O24: =Data!AD170 -> 48.42 | R24: =K23-K24+C24 -> 2755.73 | S24: 160 | T24: 300 | U24: 200 | V24: 200 | Z24: =Data!F164 -> 181.02 | AA24: =Data!F163 -> 451.51 | AB24: =Data!I163 -> 140 | AC24: =SUM(Data!I164:I171) -> 86.34 | AD24: =SUM(Data!F163:F171) -> 2529.55 | AE24: =SUM(Data!I163:I171) -> 226.34 | AF24: =AD24+AE24 -> 2755.89 | AG24: =C24-AF24 -> 2114.11 | AH24: =D24-D23 -> 2114.11 | AI24: =C24-R24 -> 2114.27 | AJ24: =K24-K23 -> 2114.27 | AK24: =AG24-AH24 -> 0 | AL24: =AI24-AJ24 -> 0 | AM24: =AG24-AG23 -> 1401.05 | AN24: =AH24-AH23 -> 1401.05 | AO24: =AJ24-AJ23 -> 1393.91 | AP24: =AN24-AM24 -> 0 | AQ24: =AO24-AN24 -> -7.14 | AR24: =K24-D24 -> 37.7 | AS24: =AI24-AG24 -> 0.16 | AT24: =AJ24-AH24 -> 0.16 | AU24: =ABS(AR24/K24) -> 0.0031999212 | AV24: =ABS(AS24/AI24) -> 7.5676238e-05 | AW24: =ABS(AR24/AVERAGE(K24,D24)) -> 0.0032050492 | AX24: =ABS((AG24-AH24)/AVERAGE(AG24,AH24)) -> 4.3020217e-16 | BP24: =ABS((AR25-AS25)/((ABS(AR25)+ABS(AS25))/2))/10 -> 0.2 | BT24: =16/31 -> 0.51612903 | BU24: =BT24*1000 -> 516.12903 | BW24: =Health!N35 -> 157.45
B25: 44562 | C25: =SUM(Data!C175:C182) -> 3000 | D25: =Data!Q183 -> 12613.77 | E25: =Data!Q180 -> 563.81 | F25: =Data!Q181 -> 7149.96 | G25: =Data!Q182 -> 4900 | K25: =Data!U183 -> 12636.22 | L25: =Data!U180 -> 568.53 | M25: =Data!U182 -> 4900 | N25: =Data!U181 -> 7167.69 | O25: =Data!AD181 -> 56.57 | R25: =K24-K25+C25 -> 2145.32 | S25: 160 | T25: 350 | U25: 100 | V25: 150 | Z25: =Data!F175 -> 200.77 | AA25: =Data!F174 -> 348.52 | AB25: =Data!I174 -> 110 | AC25: =SUM(Data!I175:I182) -> 257.53 | AD25: =SUM(Data!F174:F182) -> 1762.54 | AE25: =SUM(Data!I174:I182) -> 367.53 | AF25: =AD25+AE25 -> 2130.07 | AG25: =C25-AF25 -> 869.93 | AH25: =D25-D24 -> 869.93 | AI25: =C25-R25 -> 854.68 | AJ25: =K25-K24 -> 854.68 | AK25: =AG25-AH25 -> 0 | AL25: =AI25-AJ25 -> 0 | AM25: =AG25-AG24 -> -1244.18 | AN25: =AH25-AH24 -> -1244.18 | AO25: =AJ25-AJ24 -> -1259.59 | AP25: =AN25-AM25 -> 0 | AQ25: =AO25-AN25 -> -15.41 | AR25: =K25-D25 -> 22.45 | AS25: =AI25-AG25 -> -15.25 | AT25: =AJ25-AH25 -> -15.25 | AU25: =ABS(AR25/K25) -> 0.0017766389 | AV25: =ABS(AS25/AI25) -> 0.017842935 | AW25: =ABS(AR25/AVERAGE(K25,D25)) -> 0.0017782185 | AX25: =ABS((AG25-AH25)/AVERAGE(AG25,AH25)) -> 5.2274016e-16 | BP25: =ABS((AR26-AS26)/((ABS(AR26)+ABS(AS26))/2))/10 -> 0.09065213 | BT25: =16/31 -> 0.51612903 | BU25: =BT25*1000 -> 516.12903 | BW25: =Health!N36 -> 160.6
B26: 44593 | C26: =SUM(Data!C185:C191) -> 3000 | D26: =Data!Q192 -> 13715.39 | E26: =Data!Q189 -> 965.43 | F26: =Data!Q190 -> 7449.96 | G26: =Data!Q191 -> 5300 | K26: =Data!U192 -> 13751.38 | L26: =Data!U189 -> 975.64 | M26: =Data!U191 -> 5300 | N26: =Data!U190 -> 7475.74 | O26: =Data!AD190 -> 62.06 | R26: =K25-K26+C26 -> 1884.84 | S26: 160 | T26: 350 | U26: 100 | V26: 150 | Z26: =Data!F186 -> 191.03 | AA26: =Data!F185 -> 307.1 | AB26: =Data!I185 -> 175 | AC26: =SUM(Data!I186:I191) -> 114.25 | AD26: =SUM(Data!F185:F191) -> 1609.13 | AE26: =SUM(Data!I185:I191) -> 289.25 | AF26: =AD26+AE26 -> 1898.38 | AG26: =C26-AF26 -> 1101.62 | AH26: =D26-D25 -> 1101.62 | AI26: =C26-R26 -> 1115.16 | AJ26: =K26-K25 -> 1115.16 | AK26: =AG26-AH26 -> 0 | AL26: =AI26-AJ26 -> 0 | AM26: =AG26-AG25 -> 231.69 | AN26: =AH26-AH25 -> 231.69 | AO26: =AJ26-AJ25 -> 260.48 | AP26: =AN26-AM26 -> 4.5474735e-13 | AQ26: =AO26-AN26 -> 28.79 | AR26: =K26-D26 -> 35.99 | AS26: =AI26-AG26 -> 13.54 | AT26: =AJ26-AH26 -> 13.54 | AU26: =ABS(AR26/K26) -> 0.0026171919 | AV26: =ABS(AS26/AI26) -> 0.012141755 | AW26: =ABS(AR26/AVERAGE(K26,D26)) -> 0.0026206212 | AX26: =ABS((AG26-AH26)/AVERAGE(AG26,AH26)) -> 8.2559749e-16 | BP26: =ABS((AR27-AS27)/((ABS(AR27)+ABS(AS27))/2))/10 -> 0.14375874 | BT26: =19/29 -> 0.65517241 | BU26: =BT26*1000 -> 655.17241 | BW26: =Health!N37 -> 160.52
B27: 44621 | C27: =SUM(Data!C194:C201) -> 3200 | D27: =Data!Q202 -> 14195.84 | E27: =Data!Q199 -> 745.88 | F27: =Data!Q200 -> 7749.96 | G27: =Data!Q201 -> 5700 | K27: =Data!U202 -> 14238.87 | L27: =Data!U199 -> 754.07 | M27: =Data!U201 -> 5700 | N27: =Data!U200 -> 7784.8 | O27: =Data!AD200 -> 64.04 | R27: =K26-K27+C27 -> 2712.51 | S27: 160 | T27: 350 | U27: 100 | V27: 150 | Z27: =Data!F195 -> 218.19 | AA27: =Data!F194 -> 564.87 | AB27: =Data!I194 -> 170 | AC27: =SUM(Data!I195:I201) -> 671.49 | AD27: =SUM(Data!F194:F201) -> 1878.06 | AE27: =SUM(Data!I194:I201) -> 841.49 | AF27: =AD27+AE27 -> 2719.55 | AG27: =C27-AF27 -> 480.45 | AH27: =D27-D26 -> 480.45 | AI27: =C27-R27 -> 487.49 | AJ27: =K27-K26 -> 487.49 | AK27: =AG27-AH27 -> 9.094947e-13 | AL27: =AI27-AJ27 -> 0 | AM27: =AG27-AG26 -> -621.17 | AN27: =AH27-AH26 -> -621.17 | AO27: =AJ27-AJ26 -> -627.67 | AP27: =AN27-AM27 -> -1.8189894e-12 | AQ27: =AO27-AN27 -> -6.5 | AR27: =K27-D27 -> 43.03 | AS27: =AI27-AG27 -> 7.04 | AT27: =AJ27-AH27 -> 7.04 | AU27: =ABS(AR27/K27) -> 0.0030220095 | AV27: =ABS(AS27/AI27) -> 0.014441322 | AW27: =ABS(AR27/AVERAGE(K27,D27)) -> 0.0030265827 | AX27: =ABS((AG27-AH27)/AVERAGE(AG27,AH27)) -> 1.8930059e-15 | BP27: =ABS((AR28-AS28)/((ABS(AR28)+ABS(AS28))/2))/10 -> 0.18471775 | BT27: =19/31 -> 0.61290323 | BU27: =BT27*1000 -> 612.90323 | BW27: =Health!N38 -> 162.4
B28: 44652 | C28: =SUM(Data!C204:C212) -> 3000 | D28: =Data!Q213 -> 10253.7 | E28: =Data!Q210 -> 503.74 | F28: =Data!Q211 -> 3749.96 | G28: =Data!Q212 -> 6000 | K28: =Data!U213 -> 10251.92 | L28: =Data!U210 -> 457.08 | M28: =Data!U212 -> 6000 | N28: =Data!U211 -> 3794.84 | O28: =Data!AD211 -> 54.47 | R28: =K27-K28+C28 -> 6986.95 | S28: 200 | T28: 400 | U28: 100 | V28: 150 | Z28: =Data!F205 -> 281.74 | AA28: =Data!F204 -> 383.9 | AB28: =Data!I204 -> 120 | AC28: =SUM(Data!I205:I212) -> 300.01 | AD28: =SUM(Data!F204:F212) -> 6522.13 | AE28: =SUM(Data!I204:I212) -> 420.01 | AF28: =AD28+AE28 -> 6942.14 | AG28: =C28-AF28 -> -3942.14 | AH28: =D28-D27 -> -3942.14 | AI28: =C28-R28 -> -3986.95 | AJ28: =K28-K27 -> -3986.95 | AK28: =AG28-AH28 -> 0 | AL28: =AI28-AJ28 -> 0 | AM28: =AG28-AG27 -> -4422.59 | AN28: =AH28-AH27 -> -4422.59 | AO28: =AJ28-AJ27 -> -4474.44 | AP28: =AN28-AM28 -> 0 | AQ28: =AO28-AN28 -> -51.85 | AR28: =K28-D28 -> -1.78 | AS28: =AI28-AG28 -> -44.81 | AT28: =AJ28-AH28 -> -44.81 | AU28: =ABS(AR28/K28) -> 0.00017362601 | AV28: =ABS(AS28/AI28) -> 0.011239168 | AW28: =ABS(AR28/AVERAGE(K28,D28)) -> 0.00017361094 | AX28: =ABS((AG28-AH28)/AVERAGE(AG28,AH28)) -> 2.3071091e-16 | BP28: =ABS((AR29-AS29)/((ABS(AR29)+ABS(AS29))/2))/10 -> 0.0039634825 | BT28: =24/30 -> 0.8 | BU28: =BT28*1000 -> 800 | BW28: =Health!N39 -> 162.55
B29: 44682 | C29: =SUM(Data!C215:C224) -> 2169 | D29: =Data!Q225 -> 9798.64 | E29: =Data!Q222 -> 1548.68 | F29: =Data!Q223 -> 2249.96 | G29: =Data!Q224 -> 6000 | K29: =Data!U225 -> 9752.84 | L29: =Data!U222 -> 1455.98 | M29: =Data!U224 -> 6000 | N29: =Data!U223 -> 2296.86 | O29: =Data!AD223 -> 95.58 | R29: =K28-K29+C29 -> 2668.08 | S29: 200 | T29: 400 | U29: 100 | V29: 150 | Z29: =Data!F216 -> 239.45 | AA29: =Data!F215 -> 581.74 | AB29: =Data!I215 -> 140 | AC29: =SUM(Data!I216:I224) -> 281.3 | AD29: =SUM(Data!F215:F224) -> 2202.76 | AE29: =SUM(Data!I215:I224) -> 421.3 | AF29: =AD29+AE29 -> 2624.06 | AG29: =C29-AF29 -> -455.06 | AH29: =D29-D28 -> -455.06 | AI29: =C29-R29 -> -499.08 | AJ29: =K29-K28 -> -499.08 | AK29: =AG29-AH29 -> -4.5474735e-13 | AL29: =AI29-AJ29 -> 0 | AM29: =AG29-AG28 -> 3487.08 | AN29: =AH29-AH28 -> 3487.08 | AO29: =AJ29-AJ28 -> 3487.87 | AP29: =AN29-AM29 -> 0 | AQ29: =AO29-AN29 -> 0.79 | AR29: =K29-D29 -> -45.8 | AS29: =AI29-AG29 -> -44.02 | AT29: =AJ29-AH29 -> -44.02 | AU29: =ABS(AR29/K29) -> 0.004696068 | AV29: =ABS(AS29/AI29) -> 0.088202292 | AW29: =ABS(AR29/AVERAGE(K29,D29)) -> 0.0046850673 | AX29: =ABS((AG29-AH29)/AVERAGE(AG29,AH29)) -> 9.9931295e-16 | BP29: =ABS((AR30-AS30)/((ABS(AR30)+ABS(AS30))/2))/10 -> 0.093526649 | BT29: =24/31 -> 0.77419355 | BU29: =BT29*1000 -> 774.19355 | BW29: =Health!N40 -> 164.5
B30: 44713 | C30: =SUM(Data!C227:C232) -> 1582.04 | D30: =Data!Q233 -> 9319.54 | E30: =Data!Q230 -> 2069.58 | F30: =Data!Q231 -> 1249.96 | G30: =Data!Q232 -> 6000 | K30: =Data!U233 -> 9247.67 | L30: =Data!U230 -> 1947.8 | M30: =Data!U232 -> 6000 | N30: =Data!U231 -> 1299.87 | O30: =Data!AD231 -> 97.93 | R30: =K29-K30+C30 -> 2087.21 | S30: 200 | T30: 400 | U30: 80 | V30: 150 | Z30: =Data!F228 -> 293.08 | AA30: =Data!F227 -> 674.58 | AB30: =Data!I227 -> 160 | AC30: =SUM(Data!I227:I232) -> 242.48 | AD30: =SUM(Data!F227:F232) -> 1818.66 | AE30: =SUM(Data!I227:I233) -> 242.48 | AF30: =AD30+AE30 -> 2061.14 | AG30: =C30-AF30 -> -479.1 | AH30: =D30-D29 -> -479.1 | AI30: =C30-R30 -> -505.17 | AJ30: =K30-K29 -> -505.17 | AK30: =AG30-AH30 -> 4.5474735e-13 | AL30: =AI30-AJ30 -> 0 | AM30: =AG30-AG29 -> -24.04 | AN30: =AH30-AH29 -> -24.04 | AO30: =AJ30-AJ29 -> -6.09 | AP30: =AN30-AM30 -> -9.094947e-13 | AQ30: =AO30-AN30 -> 17.95 | AR30: =K30-D30 -> -71.87 | AS30: =AI30-AG30 -> -26.07 | AT30: =AJ30-AH30 -> -26.07 | AU30: =ABS(AR30/K30) -> 0.0077716874 | AV30: =ABS(AS30/AI30) -> 0.05160639 | AW30: =ABS(AR30/AVERAGE(K30,D30)) -> 0.0077416047 | AX30: =ABS((AG30-AH30)/AVERAGE(AG30,AH30)) -> 9.4917001e-16 | BP30: =ABS((AR31-AS31)/((ABS(AR31)+ABS(AS31))/2))/10 -> 0.2 | BT30: =24/30 -> 0.8 | BU30: =BT30*1000 -> 800 | BW30: =Health!N41 -> 166.28
B31: 44743 | C31: =SUM(Data!C235:C244) -> 1567.04 | D31: =Data!Q245 -> 8643.57 | E31: =Data!Q242 -> 1793.61 | F31: =Data!Q243 -> 849.96 | G31: =Data!Q244 -> 6000 | K31: =Data!U245 -> 8597.33 | L31: =Data!U242 -> 1688.45 | M31: =Data!U244 -> 6000 | N31: =Data!U243 -> 908.88 | O31: =Data!AD243 -> 113.49 | R31: =K30-K31+C31 -> 2217.38 | S31: 200 | T31: 500 | U31: 0 | V31: 150 | Z31: =Data!F236 -> 228.94 | AA31: =Data!F235 -> 543.72 | AB31: =Data!I235 -> 140 | AC31: =SUM(Data!I236:I244) -> 367.34 | AD31: =SUM(Data!F235:F244) -> 1735.67 | AE31: =SUM(AC31+AB31) -> 507.34 | AF31: =AD31+AE31 -> 2243.01 | AG31: =C31-AF31 -> -675.97 | AH31: =D31-D30 -> -675.97 | AI31: =C31-R31 -> -650.34 | AJ31: =K31-K30 -> -650.34 | AK31: =AG31-AH31 -> 0 | AL31: =AI31-AJ31 -> 0 | AM31: =AG31-AG30 -> -196.87 | AN31: =AH31-AH30 -> -196.87 | AO31: =AJ31-AJ30 -> -145.17 | AP31: =AN31-AM31 -> 9.094947e-13 | AQ31: =AO31-AN31 -> 51.7 | AR31: =K31-D31 -> -46.24 | AS31: =AI31-AG31 -> 25.63 | AT31: =AJ31-AH31 -> 25.63 | AU31: =ABS(AR31/K31) -> 0.005378414 | AV31: =ABS(AS31/AI31) -> 0.039410155 | AW31: =ABS(AR31/AVERAGE(K31,D31)) -> 0.0053639891 | AX31: =ABS((AG31-AH31)/AVERAGE(AG31,AH31)) -> 6.7273304e-16 | BP31: =ABS((AR32-AS32)/((ABS(AR32)+ABS(AS32))/2))/10 -> 0.15418473 | BT31: =25/30 -> 0.83333333 | BU31: =BT31*1000 -> 833.33333 | BW31: =Health!N42 -> 168.55
B32: 44774 | C32: =SUM(Data!C247:C256) -> 0 | D32: =Data!Q257 -> 6215.33 | E32: =Data!Q254 -> 225.37 | F32: =Data!Q255 -> 289.96 | G32: =Data!Q256 -> 5700 | K32: =Data!U257 -> 6162.22 | L32: =Data!U254 -> 149.33 | M32: =Data!U256 -> 5700 | N32: =Data!U255 -> 312.89 | O32: =Data!AD255 -> 105.55 | R32: =K31-K32+C32 -> 2435.11 | S32: 200 | T32: 500 | U32: 0 | V32: 150 | Z32: =Data!F248 -> 216.94 | AA32: =Data!F247 -> 498.76 | AB32: =Data!I247 -> 100 | AC32: =SUM(Data!I248:I256) -> 600.46 | AD32: =SUM(Data!F247:F256) -> 1727.78 | AE32: =SUM(Data!I247:I256) -> 700.46 | AF32: =AD32+AE32 -> 2428.24 | AG32: =C32-AF32 -> -2428.24 | AH32: =D32-D31 -> -2428.24 | AI32: =C32-R32 -> -2435.11 | AJ32: =K32-K31 -> -2435.11 | AK32: =AG32-AH32 -> 0 | AL32: =AI32-AJ32 -> 0 | AM32: =AG32-AG31 -> -1752.27 | AN32: =AH32-AH31 -> -1752.27 | AO32: =AJ32-AJ31 -> -1784.77 | AP32: =AN32-AM32 -> 0 | AQ32: =AO32-AN32 -> -32.5 | AR32: =K32-D32 -> -53.11 | AS32: =AI32-AG32 -> -6.87 | AT32: =AJ32-AH32 -> -6.87 | AU32: =ABS(AR32/K32) -> 0.0086186472 | AV32: =ABS(AS32/AI32) -> 0.0028212278 | AW32: =ABS(AR32/AVERAGE(K32,D32)) -> 0.008581666 | AX32: =ABS((AG32-AH32)/AVERAGE(AG32,AH32)) -> 0 | BP32: =ABS((AR33-AS33)/((ABS(AR33)+ABS(AS33))/2))/10 -> 0.2 | BT32: =27/31 -> 0.87096774 | BU32: =BT32*1000 -> 870.96774 | BW32: =Health!N43 -> 169.95
B33: 44805 | C33: =SUM(Data!C259:C265) -> 1507.04 | D33: =Data!Q266 -> 5591.15 | E33: =Data!Q263 -> 1501.19 | F33: =Data!Q264 -> 489.96 | G33: =Data!Q265 -> 3600 | K33: =Data!U266 -> 5542.64 | L33: =Data!U263 -> 1521.75 | M33: =Data!U265 -> 3600 | N33: =Data!U264 -> 420.89 | O33: =Data!AD264 -> 103.66 | R33: =K32-K33+C33 -> 2126.62 | S33: 200 | T33: 500 | U33: 0 | V33: 150 | Z33: =Data!F260 -> 184.94 | AA33: =Data!F259 -> 673.68 | AB33: 0 | AC33: =SUM(Data!I259:I265) -> 332.44 | AD33: =SUM(Data!F259:F265) -> 1798.78 | AE33: =SUM(Data!I259:I265) -> 332.44 | AF33: =AD33+AE33 -> 2131.22 | AG33: =C33-AF33 -> -624.18 | AH33: =D33-D32 -> -624.18 | AI33: =C33-R33 -> -619.58 | AJ33: =K33-K32 -> -619.58 | AK33: =AG33-AH33 -> 0 | AL33: =AI33-AJ33 -> 0 | AM33: =AG33-AG32 -> 1804.06 | AN33: =AH33-AH32 -> 1804.06 | AO33: =AJ33-AJ32 -> 1815.53 | AP33: =AN33-AM33 -> 0 | AQ33: =AO33-AN33 -> 11.47 | AR33: =K33-D33 -> -48.51 | AS33: =AI33-AG33 -> 4.6 | AT33: =AJ33-AH33 -> 4.6 | AU33: =ABS(AR33/K33) -> 0.008752147 | AV33: =ABS(AS33/AI33) -> 0.0074243843 | AW33: =ABS(AR33/AVERAGE(K33,D33)) -> 0.0087140138 | AX33: =ABS((AG33-AH33)/AVERAGE(AG33,AH33)) -> 0 | BP33: =ABS((AR34-AS34)/((ABS(AR34)+ABS(AS34))/2))/10 -> 0.065039887 | BT33: =26/30 -> 0.86666667 | BU33: =BT33*1000 -> 866.66667 | BW33: =Health!N44 -> 171.68
B34: 44835 | C34: =SUM(Data!C268:C276) -> 1507.04 | D34: =Data!Q277 -> 4637.26 | E34: =Data!Q274 -> 1647.3 | F34: =Data!Q275 -> 489.96 | G34: =Data!Q276 -> 2500 | K34: =Data!U277 -> 4538.42 | L34: =Data!Q274 -> 1647.3 | M34: =Data!Q276 -> 2500 | N34: =Data!Q275 -> 489.96 | O34: =Data!AD275 -> 109.32 | R34: =K33-K34+C34 -> 2511.26 | S34: 200 | T34: 400 | U34: 0 | V34: 150 | Z34: =Data!F269 -> 205.16 | AA34: =Data!F268 -> 619.2 | AB34: 0 | AC34: =SUM(Data!I268:I276) -> 428.4 | AD34: =SUM(Data!F268:F276) -> 2032.53 | AE34: =SUM(Data!I268:I276) -> 428.4 | AF34: =AD34+AE34 -> 2460.93 | AG34: =C34-AF34 -> -953.89 | AH34: =D34-D33 -> -953.89 | AI34: =C34-R34 -> -1004.22 | AJ34: =K34-K33 -> -1004.22 | AK34: =AG34-AH34 -> 0 | AL34: =AI34-AJ34 -> 0 | AM34: =AG34-AG33 -> -329.71 | AN34: =AH34-AH33 -> -329.71 | AO34: =AJ34-AJ33 -> -384.64 | AP34: =AN34-AM34 -> -4.5474735e-13 | AQ34: =AO34-AN34 -> -54.93 | AR34: =K34-D34 -> -98.84 | AS34: =AI34-AG34 -> -50.33 | AT34: =AJ34-AH34 -> -50.33 | AU34: =ABS(AR34/K34) -> 0.021778504 | AV34: =ABS(AS34/AI34) -> 0.0501185 | AW34: =ABS(AR34/AVERAGE(K34,D34)) -> 0.021543907 | AX34: =ABS((AG34-AH34)/AVERAGE(AG34,AH34)) -> 4.7672934e-16 | BP34: =ABS((AR35-AS35)/((ABS(AR35)+ABS(AS35))/2))/10 -> 0.12891613 | BT34: =22/31 -> 0.70967742 | BU34: =BT34*1000 -> 709.67742 | BW34: =Health!N45 -> 178.06667
B35: 44866 | C35: =SUM(Data!C279:C288) -> 1507.04 | D35: =Data!Q289 -> 3809.64 | E35: =Data!Q286 -> 1519.68 | F35: =Data!Q287 -> 489.96 | G35: =Data!Q288 -> 1800 | K35: =Data!U289 -> 3683.55 | L35: =Data!U286 -> 1443.66 | M35: =Data!U288 -> 1800 | N35: =Data!U287 -> 439.89 | O35: =Data!AD287 -> 91.37 | R35: =K34-K35+C35 -> 2361.91 | S35: 160 | T35: 350 | U35: 0 | V35: 150 | Z35: =Data!F280 -> 178.95 | AA35: =Data!F279 -> 523.52 | AB35: 0 | AC35: =SUM(Data!I279:I288) -> 281.03 | AD35: =SUM(Data!F279:F288) -> 2053.63 | AE35: =SUM(Data!I279:I288) -> 281.03 | AF35: =AD35+AE35 -> 2334.66 | AG35: =C35-AF35 -> -827.62 | AH35: =D35-D34 -> -827.62 | AI35: =C35-R35 -> -854.87 | AJ35: =K35-K34 -> -854.87 | AK35: =AG35-AH35 -> 0 | AL35: =AI35-AJ35 -> 0 | AM35: =AG35-AG34 -> 126.27 | AN35: =AH35-AH34 -> 126.27 | AO35: =AJ35-AJ34 -> 149.35 | AP35: =AN35-AM35 -> 4.5474735e-13 | AQ35: =AO35-AN35 -> 23.08 | AR35: =K35-D35 -> -126.09 | AS35: =AI35-AG35 -> -27.25 | AT35: =AJ35-AH35 -> -27.25 | AU35: =ABS(AR35/K35) -> 0.034230566 | AV35: =ABS(AS35/AI35) -> 0.031876192 | AW35: =ABS(AR35/AVERAGE(K35,D35)) -> 0.033654558 | AX35: =ABS((AG35-AH35)/AVERAGE(AG35,AH35)) -> 0 | BP35: =ABS((AR36-AS36)/((ABS(AR36)+ABS(AS36))/2))/10 -> 0.12645815 | BT35: =22/30 -> 0.73333333 | BU35: =BT35*1000 -> 733.33333 | BW35: =Health!N46 -> 180.75
B36: 44896 | C36: =SUM(Data!C291:C300) -> 1557.04 | D36: =Data!Q301 -> 2792.53 | E36: =Data!Q298 -> 807.57 | F36: =Data!Q299 -> 484.96 | G36: =Data!Q300 -> 1500 | K36: =Data!U301 -> 2636.23 | L36: =Data!U298 -> 693.33 | M36: =Data!U300 -> 1500 | N36: =Data!U299 -> 442.9 | O36: =Data!AD299 -> 88.54 | R36: =K35-K36+C36 -> 2604.36 | S36: 160 | T36: 350 | U36: 0 | V36: 150 | Z36: =Data!F292 -> 157 | AA36: =Data!F291 -> 397.56 | AB36: =Data!I299 -> 70 | AC36: =SUM(Data!I291:I299) -> 521.12 | AD36: =SUM(Data!F291:F300) -> 2048.03 | AE36: =SUM(Data!I291:I299) -> 521.12 | AF36: =AD36+AE36 -> 2569.15 | AG36: =C36-AF36 -> -1012.11 | AH36: =D36-D35 -> -1017.11 | AI36: =C36-R36 -> -1047.32 | AJ36: =K36-K35 -> -1047.32 | AK36: =AG36-AH36 -> 5 | AL36: =AI36-AJ36 -> 0 | AM36: =AG36-AG35 -> -184.49 | AN36: =AH36-AH35 -> -189.49 | AO36: =AJ36-AJ35 -> -192.45 | AP36: =AN36-AM36 -> -5 | AQ36: =AO36-AN36 -> -2.96 | AR36: =K36-D36 -> -156.3 | AS36: =AI36-AG36 -> -35.21 | AT36: =AJ36-AH36 -> -30.21 | AU36: =ABS(AR36/K36) -> 0.059289212 | AV36: =ABS(AS36/AI36) -> 0.033619142 | AW36: =ABS(AR36/AVERAGE(K36,D36)) -> 0.05758221 | AX36: =ABS((AG36-AH36)/AVERAGE(AG36,AH36)) -> 0.0049280019 | BP36: =ABS((AR37-AS37)/((ABS(AR37)+ABS(AS37))/2))/10 -> 0.2 | BT36: =26/31 -> 0.83870968 | BU36: =BT36*1000 -> 838.70968 | BW36: =Health!N47 -> 180.05
B37: 44927 | C37: =SUM(Data!C303:C311) -> 0 | D37: =Data!Q312 -> 988.79 | E37: =Data!Q309 -> 353.83 | F37: =Data!Q310 -> 434.96 | G37: =Data!Q311 -> 200 | K37: =Data!U312 -> 872.24 | L37: =Data!U309 -> 274.34 | M37: =Data!U311 -> 200 | N37: =Data!U310 -> 397.9 | O37: =Data!AD310 -> 123.28 | R37: =K36-K37+C37 -> 1763.99 | S37: 160 | T37: 350 | U37: 0 | V37: 150 | Z37: =Data!F304 -> 169.01 | AA37: =Data!F303 -> 408.37 | AB37: 0 | AC37: =SUM(Data!I303:I311) -> 338.2 | AD37: =SUM(Data!F303:F311) -> 1465.54 | AE37: =SUM(Data!I303:I311) -> 338.2 | AF37: =AD37+AE37 -> 1803.74 | AG37: =C37-AF37 -> -1803.74 | AH37: =D37-D36 -> -1803.74 | AI37: =C37-R37 -> -1763.99 | AJ37: =K37-K36 -> -1763.99 | AK37: =AG37-AH37 -> 0 | AL37: =AI37-AJ37 -> 0 | AM37: =AG37-AG36 -> -791.63 | AN37: =AH37-AH36 -> -786.63 | AO37: =AJ37-AJ36 -> -716.67 | AP37: =AN37-AM37 -> 5 | AQ37: =AO37-AN37 -> 69.96 | AR37: =K37-D37 -> -116.55 | AS37: =AI37-AG37 -> 39.75 | AT37: =AJ37-AH37 -> 39.75 | AU37: =ABS(AR37/K37) -> 0.13362148 | AV37: =ABS(AS37/AI37) -> 0.022534141 | AW37: =ABS(AR37/AVERAGE(K37,D37)) -> 0.12525322 | AX37: =ABS((AG37-AH37)/AVERAGE(AG37,AH37)) -> 0 | BP37: =ABS((AR38-AS38)/((ABS(AR38)+ABS(AS38))/2))/10 -> 0.2 | BT37: =25/31 -> 0.80645161 | BU37: =BT37*1000 -> 806.45161 | BW37: =Health!N48 -> 178.2
B38: 44958 | C38: =SUM(Data!C314:C319) -> 1917.79 | D38: =Data!Q320 -> 1469.33 | E38: =Data!Q317 -> 1134.37 | F38: =Data!Q318 -> 334.96 | G38: =Data!Q319 -> 0 | K38: =Data!U320 -> 1435.68 | L38: =Data!U317 -> 1138.78 | M38: =Data!U319 -> 0 | N38: =Data!U318 -> 296.9 | O38: =Data!AD318 -> 125.51 | R38: =K37-K38+C38 -> 1354.35 | S38: 160 | T38: 350 | U38: 0 | V38: 150 | Z38: =Data!F315 -> 170.38 | AA38: =Data!F314 -> 232.7 | AB38: 0 | AC38: =SUM(Data!I314:I319) -> 289.17 | AD38: =SUM(Data!F314:F319) -> 1148.08 | AE38: =AC38 -> 289.17 | AF38: =AD38+AE38 -> 1437.25 | AG38: =C38-AF38 -> 480.54 | AH38: =D38-D37 -> 480.54 | AI38: =C38-R38 -> 563.44 | AJ38: =K38-K37 -> 563.44 | AK38: =AG38-AH38 -> 0 | AL38: =AI38-AJ38 -> 0 | AM38: =AG38-AG37 -> 2284.28 | AN38: =AH38-AH37 -> 2284.28 | AO38: =AJ38-AJ37 -> 2327.43 | AP38: =AN38-AM38 -> 0 | AQ38: =AO38-AN38 -> 43.15 | AR38: =K38-D38 -> -33.65 | AS38: =AI38-AG38 -> 82.9 | AT38: =AJ38-AH38 -> 82.9 | AU38: =ABS(AR38/K38) -> 0.023438371 | AV38: =ABS(AS38/AI38) -> 0.1471319 | AW38: =ABS(AR38/AVERAGE(K38,D38)) -> 0.023166874 | AX38: =ABS((AG38-AH38)/AVERAGE(AG38,AH38)) -> 2.3658142e-16 | BP38: =ABS((AR39-AS39)/((ABS(AR39)+ABS(AS39))/2))/10 -> 0.035057561 | BT38: =24/29 -> 0.82758621 | BU38: =BT38*1000 -> 827.58621 | BW38: =Health!N49 -> 175.8
B39: 44986 | C39: =SUM(Data!C322:C328) -> 1917.79 | D39: =Data!Q329 -> 1951.43 | E39: =Data!Q326 -> 1456.47 | F39: =Data!Q327 -> 494.96 | G39: =Data!Q328 -> 0 | K39: =Data!U329 -> 1838.62 | L39: =Data!U326 -> 1373.71 | M39: =Data!U328 -> 0 | N39: =Data!U327 -> 464.91 | O39: =Data!AD327 -> 151.18 | R39: =K38-K39+C39 -> 1514.85 | S39: 160 | T39: 350 | U39: 0 | V39: 150 | Z39: =Data!F323 -> 250.6 | AA39: =Data!F322 -> 473.38 | AB39: =Data!I325 -> 40 | AC39: =SUM(Data!I322:I328) -> 476.63 | AD39: =SUM(Data!F322:F328) -> 959.06 | AE39: =SUM(Data!I322:I328) -> 476.63 | AF39: =AD39+AE39 -> 1435.69 | AG39: =C39-AF39 -> 482.1 | AH39: =D39-D38 -> 482.1 | AI39: =C39-R39 -> 402.94 | AJ39: =K39-K38 -> 402.94 | AK39: =AG39-AH39 -> 0 | AL39: =AI39-AJ39 -> 0 | AM39: =AG39-AG38 -> 1.56 | AN39: =AH39-AH38 -> 1.56 | AO39: =AJ39-AJ38 -> -160.5 | AP39: =AN39-AM39 -> -3.4106051e-13 | AQ39: =AO39-AN39 -> -162.06 | AR39: =K39-D39 -> -112.81 | AS39: =AI39-AG39 -> -79.16 | AT39: =AJ39-AH39 -> -79.16 | AU39: =ABS(AR39/K39) -> 0.061355799 | AV39: =ABS(AS39/AI39) -> 0.19645605 | AW39: =ABS(AR39/AVERAGE(K39,D39)) -> 0.059529558 | AX39: =ABS((AG39-AH39)/AVERAGE(AG39,AH39)) -> 4.7163177e-16 | BP39: =ABS((AR40-AS40)/((ABS(AR40)+ABS(AS40))/2))/10 -> 0.083098228 | BT39: =25/31 -> 0.80645161 | BU39: =BT39*1000 -> 806.45161 | BW39: =Health!N50 -> 177.25
B40: 45017 | C40: =SUM(Data!C331:C335) -> 1917.79 | D40: =Data!Q337 -> 2535.88 | E40: =Data!Q334 -> 2035.92 | F40: =Data!Q335 -> 499.96 | G40: =Data!Q336 -> 0 | K40: =Data!U337 -> 2343.72 | L40: =Data!U334 -> 1874.79 | M40: =Data!U336 -> 0 | N40: =Data!U335 -> 468.93 | O40: =Data!AD335 -> 152.55 | R40: =K39-K40+C40 -> 1412.69 | S40: 160 | T40: 350 | U40: 0 | V40: 150 | Z40: =Data!F332 -> 153.17 | AA40: =Data!F331 -> 296 | AB40: =Data!I333 -> 90 | AC40: =SUM(Data!I331:I336) -> 703.33 | AD40: =SUM(Data!F331:F336) -> 630.01 | AE40: =SUM(Data!I331:I336) -> 703.33 | AF40: =AD40+AE40 -> 1333.34 | AG40: =C40-AF40 -> 584.45 | AH40: =D40-D39 -> 584.45 | AI40: =C40-R40 -> 505.1 | AJ40: =K40-K39 -> 505.1 | AK40: =AG40-AH40 -> 0 | AL40: =AI40-AJ40 -> 0 | AM40: =AG40-AG39 -> 102.35 | AN40: =AH40-AH39 -> 102.35 | AO40: =AJ40-AJ39 -> 102.16 | AP40: =AN40-AM40 -> 4.5474735e-13 | AQ40: =AO40-AN40 -> -0.19 | AR40: =K40-D40 -> -192.16 | AS40: =AI40-AG40 -> -79.35 | AT40: =AJ40-AH40 -> -79.35 | AU40: =ABS(AR40/K40) -> 0.081989316 | AV40: =ABS(AS40/AI40) -> 0.1570976 | AW40: =ABS(AR40/AVERAGE(K40,D40)) -> 0.078760554 | AX40: =ABS((AG40-AH40)/AVERAGE(AG40,AH40)) -> 3.8903871e-16 | BP40: =ABS((AR41-AS41)/((ABS(AR41)+ABS(AS41))/2))/10 -> 0.17753141 | BT40: =21/30 -> 0.7 | BU40: =BT40*1000 -> 700 | BW40: =Health!N51 -> 177.32
B41: 45047 | C41: =SUM(Data!C339:C343) -> 1917.79 | D41: =Data!Q344 -> 2893.11 | E41: =Data!Q341 -> 2393.15 | F41: =Data!Q342 -> 499.96 | G41: =Data!Q343 -> 0 | K41: =Data!U344 -> 2688.79 | L41: =Data!U341 -> 2212.82 | M41: =Data!U343 -> 0 | N41: =Data!U342 -> 475.97 | O41: =Data!AD342 -> 145.25 | R41: =K40-K41+C41 -> 1572.72 | S41: 160 | T41: 350 | U41: 0 | V41: 150 | Z41: =Data!F340 -> 203.83 | AA41: =Data!F339 -> 337.46 | AB41: =Data!I340 -> 200 | AC41: =SUM(Data!I339:I343)-AB41 -> 654.27 | AD41: =SUM(Data!F339:F342) -> 706.29 | AE41: =SUM(Data!I339:I343) -> 854.27 | AF41: =AD41+AE41 -> 1560.56 | AG41: =C41-AF41 -> 357.23 | AH41: =D41-D40 -> 357.23 | AI41: =C41-R41 -> 345.07 | AJ41: =K41-K40 -> 345.07 | AK41: =AG41-AH41 -> 4.5474735e-13 | AL41: =AI41-AJ41 -> 0 | AM41: =AG41-AG40 -> -227.22 | AN41: =AH41-AH40 -> -227.22 | AO41: =AJ41-AJ40 -> -160.03 | AP41: =AN41-AM41 -> -6.8212103e-13 | AQ41: =AO41-AN41 -> 67.19 | AR41: =K41-D41 -> -204.32 | AS41: =AI41-AG41 -> -12.16 | AT41: =AJ41-AH41 -> -12.16 | AU41: =ABS(AR41/K41) -> 0.075989572 | AV41: =ABS(AS41/AI41) -> 0.035239227 | AW41: =ABS(AR41/AVERAGE(K41,D41)) -> 0.073208047 | AX41: =ABS((AG41-AH41)/AVERAGE(AG41,AH41)) -> 1.272982e-15 | BP41: =ABS((AR42-AS42)/((ABS(AR42)+ABS(AS42))/2))/10 -> 0.14667624 | BT41: =19/31 -> 0.61290323 | BU41: =BT41*1000 -> 612.90323 | BW41: =Health!N52 -> 178
...

Sheet Bills
Q1: Total Due
B2: Bills | N2: =SUM(N4:N29) -> 4030.395 | O2: =SUM(O4:O29) -> 4030.4 | P2: =N2-O2 -> -0.005 | Q2: =SUM(Q4:Q29) -> -0.005 | R2: =-Q2 -> 0.005
B3: Month (of Usage) | D3: OKC | E3: Date | F3: OGE | G3: Date | H3: ONG | I3: Date | J3: Cox | K3: Date | M3: Total | N3: Owe | O3: Paid | P3: Pay Date | Q3: Due
B4: 45292 | D4: 50 | F4: 43 | H4: 61 | J4: 106.3 | M4: =SUM(D4,F4,H4,J4) -> 260.3 | N4: =M4/2 -> 130.15 | O4: =Data!F433 -> 130 | Q4: =N4-O4 -> 0.15 | R4: =O4-N4 -> -0.15
B5: 45323 | M5: =SUM(D5,F5,H5,J5) -> 0 | N5: =M5/2 -> 0 | O5: =Data!F450 -> 99 | Q5: =N5-O5 -> -99 | R5: =O5-N5 -> 99
B6: 45352 | D6: 53.5 | F6: 36.4 | H6: 72.07 | J6: 106.3 | M6: =SUM(D6,F6,H6,J6) -> 268.27 | N6: =M6/2 -> 134.135 | O6: =Data!F467 -> 10 | Q6: =N6-O6 -> 124.135 | R6: =O6-N6 -> -124.135
B7: 45383 | D7: 58.67 | F7: 37.08 | H7: 68.07 | J7: 106.3 | M7: =SUM(D7,F7,H7,J7) -> 270.12 | N7: =M7/2 -> 135.06 | O7: =Data!F484 -> 30 | Q7: =N7-O7 -> 105.06 | R7: =O7-N7 -> -105.06
B8: 45413 | D8: 67.11 | F8: 53.09 | H8: 63.42 | J8: 106.3 | M8: =SUM(D8,F8,H8,J8) -> 289.92 | N8: =M8/2 -> 144.96 | O8: =Data!F501 -> 410 | Q8: =N8-O8 -> -265.04 | R8: =O8-N8 -> 265.04
B9: 45444 | D9: 67.11 | F9: 53.09 | H9: 63.42 | J9: 106.3 | M9: =SUM(D9,F9,H9,J9) -> 289.92 | N9: =M9/2 -> 144.96 | O9: =Data!F518 -> 170 | Q9: =N9-O9 -> -25.04 | R9: =O9-N9 -> 25.04
B10: 45474 | D10: 67.11 | F10: 53.09 | H10: 63.42 | J10: 106.3 | M10: =SUM(D10,F10,H10,J10) -> 289.92 | N10: =M10/2 -> 144.96 | O10: =Data!F535 -> 170 | Q10: =N10-O10 -> -25.04 | R10: =O10-N10 -> 25.04
B11: 45505 | D11: 67.11 | F11: 53.09 | H11: 63.42 | J11: 106.3 | M11: =SUM(D11,F11,H11,J11) -> 289.92 | N11: =M11/2 -> 144.96 | O11: =Data!F552 -> 170 | Q11: =N11-O11 -> -25.04 | R11: =O11-N11 -> 25.04
B12: 45536 | D12: 67.11 | F12: 136.63 | H12: 63.42 | J12: 106.3 | M12: =SUM(D12,F12,H12,J12) -> 373.46 | N12: =M12/2 -> 186.73 | O12: =Data!F569 -> 200 | P12: 45605 | Q12: =N12-O12 -> -13.27 | R12: =O12-N12 -> 13.27
B13: 45566 | D13: 70.4 | F13: =22.5+79.29 -> 101.79 | H13: =36.12+35.29 -> 71.41 | J13: 44.11 | M13: =SUM(D13,F13,H13,J13) -> 287.71 | N13: =M13/2 -> 143.855 | O13: =Data!F586 -> 200 | P13: 45652 | Q13: =N13-O13 -> -56.145 | R13: =O13-N13 -> 56.145
B14: 45597 | D14: 75.55 | F14: 76.21 | H14: 81.11 | J14: 60 | M14: =SUM(D14,F14,H14,J14) -> 292.87 | N14: =M14/2 -> 146.435 | O14: =Data!F603 -> 200 | P14: 45652 | Q14: =N14-O14 -> -53.565 | R14: =O14-N14 -> 53.565
B15: 45627 | D15: 72.54 | F15: 58.89 | H15: 73.37 | J15: 60 | M15: =SUM(D15,F15,H15,J15) -> 264.8 | N15: =M15/2 -> 132.4 | Q15: =N15-O15 -> 132.4 | R15: =O15-N15 -> -132.4
B16: 45658 | D16: 81.87 | F16: 60.23 | H16: 79.37 | J16: 60 | M16: =SUM(D16,F16,H16,J16) -> 281.47 | N16: =M16/2 -> 140.735 | O16: 75 | P16: 45716 | Q16: =N16-O16 -> 65.735 | R16: =O16-N16 -> -65.735
B17: 45689 | D17: 72.54 | F17: 59.05 | H17: 83.37 | J17: 60 | M17: =SUM(D17,F17,H17,J17) -> 274.96 | N17: =M17/2 -> 137.48 | O17: 140 | P17: 45749 | Q17: =N17-O17 -> -2.52 | R17: =O17-N17 -> 2.52
B18: 45717 | D18: 81.87 | F18: 60.09 | H18: 87.37 | J18: 60 | M18: =SUM(D18,F18,H18,J18) -> 289.33 | N18: =M18/2 -> 144.665 | O18: 120 | P18: 45777 | Q18: =N18-O18 -> 24.665 | R18: =O18-N18 -> -24.665
B19: 45748 | D19: 81.87 | F19: 57.58 | H19: 86.3 | J19: 60 | M19: =SUM(D19,F19,H19,J19) -> 285.75 | N19: =M19/2 -> 142.875 | Q19: =N19-O19 -> 142.875 | R19: =O19-N19 -> -142.875
B20: 45778 | D20: 72.54 | F20: 70.41 | H20: 86.3 | J20: 60 | M20: =SUM(D20,F20,H20,J20) -> 289.25 | N20: =M20/2 -> 144.625 | O20: 160 | P20: 45819 | Q20: =N20-O20 -> -15.375 | R20: =O20-N20 -> 15.375
B21: 45809 | D21: 73.05 | F21: 130.51 | H21: 82.3 | J21: 60 | M21: =SUM(D21,F21,H21,J21) -> 345.86 | N21: =M21/2 -> 172.93 | O21: 140 | P21: 45838 | Q21: =N21-O21 -> 32.93 | R21: =O21-N21 -> -32.93
B22: 45839 | D22: 73.05 | F22: 172.71 | H22: 82.3 | J22: 60 | M22: =SUM(D22,F22,H22,J22) -> 388.06 | N22: =M22/2 -> 194.03 | O22: 100 | P22: 45869 | Q22: =N22-O22 -> 94.03 | R22: =O22-N22 -> -94.03
B23: 45870 | M23: =SUM(D23,F23,H23,J23) -> 0 | N23: =M23/2 -> 0 | O23: 141.95 | P23: 45874 | Q23: =N23-O23 -> -141.95 | R23: =O23-N23 -> 141.95
B24: 45901 | M24: =SUM(D24,F24,H24,J24) -> 0 | N24: =M24/2 -> 0 | Q24: =N24-O24 -> 0 | R24: =O24-N24 -> 0
B25: 45931 | J25: 98 | M25: =SUM(D25,F25,H25,J25) -> 98 | N25: =M25 -> 98 | O25: 98 | Q25: =N25-O25 -> 0 | R25: =O25-N25 -> 0
B26: 45962 | F26: =22.5+39.07+20.59 -> 82.16 | H26: 153.69 | J26: 70 | M26: =SUM(D26,F26,H26,J26) -> 305.85 | N26: =M26 -> 305.85 | O26: =70+153.69+82.16 -> 305.85 | Q26: =N26-O26 -> 0 | R26: =O26-N26 -> 0
B27: 45992 | D27: 152.74 | F27: 39.83 | H27: 134.96 | J27: 70 | M27: =SUM(D27,F27,H27,J27) -> 397.53 | N27: =M27 -> 397.53 | O27: =134.96+70+152.74+39.83 -> 397.53 | Q27: =N27-O27 -> 0 | R27: =O27-N27 -> 0
B28: 46023 | D28: 92.16 | F28: 46.52 | H28: 100.9 | J28: 70 | M28: =SUM(D28,F28,H28,J28) -> 309.58 | N28: =M28 -> 309.58 | O28: 309.58 | Q28: =N28-O28 -> 0 | R28: =O28-N28 -> 0
B29: 46054 | D29: 81.92 | H29: 101.57 | J29: 70 | M29: =SUM(D29,F29,H29,J29) -> 253.49 | N29: =M29 -> 253.49 | O29: =101.57+151.92 -> 253.49 | Q29: =N29-O29 -> 0 | R29: =O29-N29 -> 0

Sheet Bitcoin
C2: Cryptotracker_v2.0 | Q2: =H5/C8 -> 1.3319711 | S2: Liquidity = Liquid Profit when Balance = 0!
C3: USD | F3: #VALUE! | Q3: So… based on the percentage of liquidity to liquid profit, we can calculate the "realized profit".
C4: Pre | D4: Fees | E4: Post | F4: Bought/Sold
B5: Total Bought | C5: =SUM(C17:C115) -> 1145.55 | D5: =SUM(D17:D115) -> 26.55 | E5: =SUM(E17:E115) -> 1119 | F5: =SUM(F17:F115) -> 0.0211129 | G5: LIQUID PROFIT | H5: =C8-C7 -> 204.54757 | I5: =(E6+C8)/C5 -> 1.1785584 | J5: Current Market Value | L5: 69774.71 | O5: Investment Value | P5: =C5-T13 -> -35.30686 | Q5: =C8-C7 -> 204.54757 | R5: =Q5/C5 -> 0.1785584 | S5: Total Profit
